Workbook

Sheet TOC
B2: Inhaltsverzeichnis | D2: Source: | E2: https://raw.githubusercontent.com/walter-rothlin/Source-Code/master/SchulungsUnterlagen/Formelbuch_Rothlin_Walter.xlsx
B4: Mathematik | D4: Elektrotechnik | F4: Excel-Staff
B5: 45750 | C5: Einheiten umrechnen | D5: 45991 | E5: =Einheitenvorsätze!$C$2 -> Einheiten-Vorsätze | F5: 45758 | G5: =Geburtstagsliste!$C$2 -> Geburtstagsliste für 2026
B6: 45730 | C6: =Flächenberechnungen!$C$2 -> Flächenberechnungen | D6: 45944 | E6: ='Elektronische Schaltzeichen'!$C$2 -> Elektronische Schaltzeichen
B7: 46112 | C7: =Sinuskurve!C2 -> Sinus-Kurve | D7: 45932 | E7: ='Quelle mit Innenwiderstand'!$C$2 -> Quelle mit Innenwiderstand
B8: 46196 | C8: =Sinus_Cosinus!$F$2 -> Sinus / Cosinus / Tangens | D8: 46177 | E8: ='Gemischte Schaltungen'!C2 -> Gemischte Schaltungen
B9: 45772 | C9: Vektoroperationen | D9: 46184 | E9: ='LCR-Glieder an Wechselspannung'!$C$2 -> RCL-Glieder (Serieschaltung) an Wechselspannung
B10: 45870 | C10: =VektorZeitbereich!$C$2 -> Sinusförmige Signale im Zeitbereich / Vektoren | D10: 46035 | E10: ='Kondensator an Gleichspannung'!$C$2 -> Kondensator an Gleichspannung
B11: 45873 | C11: =Theoreme!$C$2 -> Trigonometrischen Theoreme und Identitäten | D11: 46107 | E11: =Magnetismus!$C$2 -> Magnetismus
B12: 45873 | C12: ='Fläche eines Polygones'!$C$2 -> Polygone-Fläche
B13: 46182 | C13: Spitzenwert / Effektivwert / Wellenlänge / Periodendauer
D15: 45873 | E15: =Scheinleistung!$C$2 -> Scheinleistung S [VA] - Blindleistung Q [var] - Wirkleistung P [W]
D16: 45908 | E16: ='Leistung bei Wechselstrom'!$C$2 -> Leistung bei ein-phasigem Wechselstrom
B17: Physik | D17: 45939 | E17: ='3-Phasenstrom'!$C$2 -> 3-Phasenstrom (Verkettete Spannung)
B18: 45979 | C18: =Kinematik_1!$C$2 -> Kinematik I | D18: 45870 | E18: =Fourierreihe!$C$2 -> Fourierreihe
B19: 45998 | C19: ='Kinematik_1 (Weg-Zeit)'!$C$2 -> Weg-Zeit Diagramm (Kinematik I)
B21: 46032 | C21: Kinematik_2 | D21: 46149 | E21: Belasteter Spannungsteiler
B22: 45701 | C22: Kinematik 2 Berechnungen
B23: 45998 | C23: ='Kinematik_2 (Weg-Zeit)'!$C$2 -> Weg-Zeit Diagramm (Kinematik II)
B25: 45786 | C25: Schiefe Ebene

Sheet Gemischte Schaltungen
C2: Gemischte Schaltungen
P5: R1 | Q5: = | R5: 0.5 | S5: Ω | U5: =U59 -> U1 | V5: =V59 -> = | W5: =W59 -> 0.38502674 | X5: =X59 -> V | Z5: =U98 -> I1 = I23 = I123 | AA5: =V98 -> = | AB5: =W98 -> 0.77005348 | AC5: =X98 -> A
P6: R2 | Q6: = | R6: 0.5 | S6: Ω | U6: =U62 -> U1 = U2 = U23 | V6: =V62 -> = | W6: =W62 -> 0.25668449 | X6: =X62 -> V | Z6: =U18 -> I2 | AA6: =V18 -> = | AB6: =W18 -> 0.51336898 | AC6: =X18 -> A
P7: R3 | Q7: = | R7: 1 | S7: Ω | U7: =U62 -> U1 = U2 = U23 | V7: =V62 -> = | W7: =W62 -> 0.25668449 | X7: =X62 -> V | Z7: =U21 -> I3 | AA7: =V21 -> = | AB7: =W21 -> 0.25668449 | AC7: =X21 -> A
P8: R4 | Q8: = | R8: 1 | S8: Ω | U8: =U88 -> U4 = U5 = U123 = U12345 | V8: =V88 -> = | W8: =W88 -> 0.64171123 | X8: =X88 -> V | Z8: =U24 -> I4 | AA8: =V24 -> = | AB8: =W24 -> 0.64171123 | AC8: =X24 -> A
P9: R5 | Q9: = | R9: 2 | S9: Ω | U9: =U88 -> U4 = U5 = U123 = U12345 | V9: =V88 -> = | W9: =W88 -> 0.64171123 | X9: =X88 -> V | Z9: =U27 -> I5 | AA9: =V27 -> = | AB9: =W27 -> 0.32085561 | AC9: =X27 -> A
P10: R6 | Q10: = | R10: 2 | S10: Ω | U10: =U144 -> U6 | V10: =V144 -> = | W10: =W144 -> 3.4652406 | X10: =X144 -> V | Z10: =U183 -> I6 = I12345 = I123456 | AA10: =V183 -> = | AB10: =W183 -> 1.7326203 | AC10: =X183 -> A
P11: R7 | Q11: = | R11: 0.5 | S11: Ω | U11: =U31 -> U7 | V11: =V31 -> = | W11: =W31 -> 2.0534759 | X11: =X31 -> V | Z11: =U68 -> I7 = I8 = I78 | AA11: =V68 -> = | AB11: =W68 -> 4.1069519 | AC11: =X68 -> A
P12: R8 | Q12: = | R12: 0.5 | S12: Ω | U12: =U34 -> U8 | V12: =V34 -> = | W12: =W34 -> 2.0534759 | X12: =X34 -> V | Z12: =U68 -> I7 = I8 = I78 | AA12: =V68 -> = | AB12: =W68 -> 4.1069519 | AC12: =X68 -> A
P13: R9 | Q13: = | R13: 2 | S13: Ω | U13: =U172 -> U9 = U123456789 = U78 = U123456 | V13: =V172 -> = | W13: =W172 -> 4.1069519 | X13: =X172 -> V | Z13: =U65 -> I9 | AA13: =V65 -> = | AB13: =W65 -> 2.0534759 | AC13: =X65 -> A
P14: R10 | Q14: = | R14: 1 | S14: Ω | U14: =U229 -> U10 | V14: =V229 -> = | W14: =W229 -> 7.8930481 | X14: =X229 -> V | Z14: =U273 -> I10 = I123456789 = ITot | AA14: =V273 -> = | AB14: =W273 -> 7.8930481 | AC14: =X273 -> A
P15: RTot | Q15: = | R15: =R273 -> 1.5203252 | S15: V | U15: UTot | V15: = | W15: 12 | X15: V | Z15: =U273 -> I10 = I123456789 = ITot | AA15: =V273 -> = | AB15: =W273 -> 7.8930481 | AC15: =X273 -> A
U17: I2 | V17: = | W17: U23 / R2
P18: =P59 -> R23 | Q18: =Q59 -> = | R18: =R59 -> 0.33333333 | S18: =S59 -> Ω | U18: I2 | V18: = | W18: =W62/R6 -> 0.51336898 | X18: A
P19: =P62 -> R45 | Q19: =Q62 -> = | R19: =R62 -> 0.66666667 | S19: =S62 -> Ω
P20: =P65 -> R78 | Q20: =Q65 -> = | R20: =R65 -> 1 | S20: =S65 -> Ω | U20: I3 | V20: = | W20: U23 / R3
U21: I3 | V21: = | W21: =W62/R7 -> 0.25668449 | X21: A
P22: =P98 -> R123 | Q22: =Q98 -> = | R22: =R98 -> 0.83333333 | S22: =S98 -> Ω
P23: =P101 -> R789 | Q23: =Q101 -> = | R23: =R101 -> 0.66666667 | S23: =S101 -> Ω | U23: I4 | V23: = | W23: U12345 / R4
U24: I4 | V24: = | W24: =W88/R8 -> 0.64171123 | X24: A
P25: =P141 -> R12345 | Q25: =Q141 -> = | R25: =R141 -> 0.37037037 | S25: =S141 -> Ω
U26: I5 | V26: = | W26: U12345 / R5
P27: =P180 -> R123456 | Q27: =Q180 -> = | R27: =R180 -> 2.3703704 | S27: =S180 -> Ω | U27: I5 | V27: = | W27: =W88/R9 -> 0.32085561 | X27: A
P29: =P226 -> R123456789 | Q29: =Q226 -> = | R29: =R226 -> 0.5203252 | S29: =S226 -> Ω
U30: U7 | V30: = | W30: I78 * R7
P31: =P273 -> RTot | Q31: =Q273 -> = | R31: =R273 -> 1.5203252 | S31: =S273 -> Ω | U31: U7 | V31: = | W31: =W68*R11 -> 2.0534759 | X31: V
U33: U8 | V33: = | W33: I78 * R8
U34: U8 | V34: = | W34: =W68*R12 -> 2.0534759 | X34: V
C45: 1.Schritt
P48: =P6 -> R2 | Q48: =Q6 -> = | R48: =R6 -> 0.5 | S48: =S6 -> Ω | U48: =U98 -> I1 = I23 = I123 | V48: =V98 -> = | W48: =W98 -> 0.77005348 | X48: =X98 -> A
P49: =P7 -> R3 | Q49: =Q7 -> = | R49: =R7 -> 1 | S49: =S7 -> Ω | U49: =U226 -> U9 = U123456789 = U78 = U123456 | V49: =V226 -> = | W49: =W226 -> 4.1069519 | X49: =X226 -> V
P50: =P8 -> R4 | Q50: =Q8 -> = | R50: =R8 -> 1 | S50: =S8 -> Ω | U50: =P5 -> R1 | V50: =Q5 -> = | W50: =R5 -> 0.5 | X50: =S5 -> Ω
P51: =P9 -> R5 | Q51: =Q9 -> = | R51: =R9 -> 2 | S51: =S9 -> Ω | U51: =P59 -> R23 | V51: =Q59 -> = | W51: =R59 -> 0.33333333 | X51: =S59 -> Ω
P52: =P11 -> R7 | Q52: =Q11 -> = | R52: =R11 -> 0.5 | S52: =S11 -> Ω | U52: =P65 -> R78 | V52: =Q65 -> = | W52: =R65 -> 1 | X52: =S65 -> Ω
P53: =P12 -> R8 | Q53: =Q12 -> = | R53: =R12 -> 0.5 | S53: =S12 -> Ω | U53: =P13 -> R9 | V53: =Q13 -> = | W53: =R13 -> 2 | X53: =S13 -> Ω
P58: R23 | Q58: = | R58: R2||R3 | U58: U1 | V58: = | W58: I123 * R1
P59: R23 | Q59: = | R59: =1/(1/R6+1/R7) -> 0.33333333 | S59: Ω | U59: U1 | V59: = | W59: =W48*W50 -> 0.38502674 | X59: V
P61: R45 | Q61: = | R61: R4||R5 | U61: U23 | V61: = | W61: I123 * R23
P62: R45 | Q62: = | R62: =1/(1/R8+1/R9) -> 0.66666667 | S62: Ω | U62: U1 = U2 = U23 | V62: = | W62: =W48*W51 -> 0.25668449 | X62: V
P64: R78 | Q64: = | R64: R7 + R8 | U64: I9 | V64: = | W64: U123456789 / R9
...

Sheet Belasteter Spannungsteiler
C2: Belasteter Spannungsteiler
H7: Regeln (Kirchhof): | K7: Gegeben: | L7: R1 = | M7: 1 | N7: k | O7: =Einheitenvorsätze!$B$61 -> Ω | P7: =VLOOKUP(N7, CHOOSE({1,2,3,4,5}, Einheitenvorsätze!A:A, Einheitenvorsätze!B:B, Einheitenvorsätze!C:C, Einheitenvorsätze!D:D, Einheitenvorsätze!E:E), 5, FALSE) -> 3 | Q7: =M7*VLOOKUP(N7, CHOOSE({1,2,3,4}, Einheitenvorsätze!A:A, Einheitenvorsätze!B:B, Einheitenvorsätze!C:C, Einheitenvorsätze!D:D), 3, FALSE) -> 1000 | R7: R11 = | S7: 2.4 | T7: k | U7: =Einheitenvorsätze!$B$61 -> Ω | V7: =VLOOKUP(T7, CHOOSE({1,2,3,4,5}, Einheitenvorsätze!A:A, Einheitenvorsätze!B:B, Einheitenvorsätze!C:C, Einheitenvorsätze!D:D, Einheitenvorsätze!E:E), 5, FALSE) -> 3 | W7: =S7*VLOOKUP(T7, CHOOSE({1,2,3,4}, Einheitenvorsätze!A:A, Einheitenvorsätze!B:B, Einheitenvorsätze!C:C, Einheitenvorsätze!D:D), 3, FALSE) -> 2400
L8: R2 = | M8: 3 | N8: k | O8: =Einheitenvorsätze!$B$61 -> Ω | P8: =VLOOKUP(N8, CHOOSE({1,2,3,4,5}, Einheitenvorsätze!A:A, Einheitenvorsätze!B:B, Einheitenvorsätze!C:C, Einheitenvorsätze!D:D, Einheitenvorsätze!E:E), 5, FALSE) -> 3 | Q8: =M8*VLOOKUP(N8, CHOOSE({1,2,3,4}, Einheitenvorsätze!A:A, Einheitenvorsätze!B:B, Einheitenvorsätze!C:C, Einheitenvorsätze!D:D), 3, FALSE) -> 3000 | R8: R22 = | S8: 7.2 | T8: k | U8: =Einheitenvorsätze!$B$61 -> Ω | V8: =VLOOKUP(T8, CHOOSE({1,2,3,4,5}, Einheitenvorsätze!A:A, Einheitenvorsätze!B:B, Einheitenvorsätze!C:C, Einheitenvorsätze!D:D, Einheitenvorsätze!E:E), 5, FALSE) -> 3 | W8: =S8*VLOOKUP(T8, CHOOSE({1,2,3,4}, Einheitenvorsätze!A:A, Einheitenvorsätze!B:B, Einheitenvorsätze!C:C, Einheitenvorsätze!D:D), 3, FALSE) -> 7200
H9: U2 = UL | L9: RL = | M9: 3 | N9: k | O9: =Einheitenvorsätze!$B$61 -> Ω | P9: =VLOOKUP(N9, CHOOSE({1,2,3,4,5}, Einheitenvorsätze!A:A, Einheitenvorsätze!B:B, Einheitenvorsätze!C:C, Einheitenvorsätze!D:D, Einheitenvorsätze!E:E), 5, FALSE) -> 3 | Q9: =M9*VLOOKUP(N9, CHOOSE({1,2,3,4}, Einheitenvorsätze!A:A, Einheitenvorsätze!B:B, Einheitenvorsätze!C:C, Einheitenvorsätze!D:D), 3, FALSE) -> 3000
H10: UIN = U1 + UL | L10: UIN = | M10: 12 | N10: – | O10: V | P10: =VLOOKUP(N10, CHOOSE({1,2,3,4,5}, Einheitenvorsätze!A:A, Einheitenvorsätze!B:B, Einheitenvorsätze!C:C, Einheitenvorsätze!D:D, Einheitenvorsätze!E:E), 5, FALSE) -> 0 | Q10: =M10*VLOOKUP(N10, CHOOSE({1,2,3,4}, Einheitenvorsätze!A:A, Einheitenvorsätze!B:B, Einheitenvorsätze!C:C, Einheitenvorsätze!D:D), 3, FALSE) -> 12
L11: R1 / R2 = | Q11: =Q7/Q8 -> 0.33333333 | R11: R11 / R22 = | W11: =W7/W8 -> 0.33333333
H12: ITotal = I2 + IL | L12: UL / UIN (Leerlauf) = | Q12: =1-Q7/(Q7+Q8) -> 0.75 | R12: UL / UIN (Leerlauf) = | W12: =1-W7/(W7+W8) -> 0.75
L13: UL (Leerlauf) = | Q13: =$M$10*Q12 -> 9 | R13: UL (Leerlauf) = | W13: =$M$10*W12 -> 9
K14: RTotal = | L14: R1 + (R2||RL)= | M14: =Q7 + (1/(1/Q8 + 1/Q9)) -> 2500 | N14: =Einheitenvorsätze!$B$61 -> Ω
K15: ITotal = | L15: UIN / RTotal = | M15: =Q10/M14 -> 0.0048 | N15: A
K16: U1 = | L16: R1 * ITotal = | M16: =Q7*M15 -> 4.8 | N16: V
K17: UL = U2 = | L17: UIN - U1 = | M17: =Q10-M16 -> 7.2 | N17: V
C26: Inc: | D26: 1 | E26: k | F26: =$D$26*VLOOKUP(E26, CHOOSE({1,2,3,4}, Einheitenvorsätze!A:A, Einheitenvorsätze!B:B, Einheitenvorsätze!C:C, Einheitenvorsätze!D:D), 3, FALSE) -> 1000
C27: RL = | D27: 0 | E27: =D27+$F$26 -> 1000 | F27: =E27+$F$26 -> 2000 | G27: =F27+$F$26 -> 3000 | H27: =G27+$F$26 -> 4000 | I27: =H27+$F$26 -> 5000 | J27: =I27+$F$26 -> 6000 | K27: =J27+$F$26 -> 7000 | L27: =K27+$F$26 -> 8000 | ... AM27: =AL27+$F$26 -> 35000
B28: RTotal = | C28: R1 + (R2||RL)= | D28: =IF(D27=0,$Q$7,$Q$7 + (1/(1/$Q$8 + 1/D27))) -> 1000 | E28: =$Q$7 + (1/(1/$Q$8 + 1/E27)) -> 1750 | F28: =$Q$7 + (1/(1/$Q$8 + 1/F27)) -> 2200 | G28: =$Q$7 + (1/(1/$Q$8 + 1/G27)) -> 2500 | H28: =$Q$7 + (1/(1/$Q$8 + 1/H27)) -> 2714.2857 | I28: =$Q$7 + (1/(1/$Q$8 + 1/I27)) -> 2875 | J28: =$Q$7 + (1/(1/$Q$8 + 1/J27)) -> 3000 | K28: =$Q$7 + (1/(1/$Q$8 + 1/K27)) -> 3100 | L28: =$Q$7 + (1/(1/$Q$8 + 1/L27)) -> 3181.8182 | ... AM28: =$Q$7 + (1/(1/$Q$8 + 1/AM27)) -> 3763.1579
B29: ITotal = | C29: UIN / RTotal = | D29: =$Q$10/D28 -> 0.012 | E29: =$Q$10/E28 -> 0.0068571429 | F29: =$Q$10/F28 -> 0.0054545455 | G29: =$Q$10/G28 -> 0.0048 | H29: =$Q$10/H28 -> 0.0044210526 | I29: =$Q$10/I28 -> 0.004173913 | J29: =$Q$10/J28 -> 0.004 | K29: =$Q$10/K28 -> 0.0038709677 | ... AM29: =$Q$10/AM28 -> 0.0031888112
B30: U1 = | C30: R1 * ITotal = | D30: =$Q$7*D29 -> 12 | E30: =$Q$7*E29 -> 6.8571429 | F30: =$Q$7*F29 -> 5.4545455 | G30: =$Q$7*G29 -> 4.8 | H30: =$Q$7*H29 -> 4.4210526 | I30: =$Q$7*I29 -> 4.173913 | J30: =$Q$7*J29 -> 4 | K30: =$Q$7*K29 -> 3.8709677 | ... AM30: =$Q$7*AM29 -> 3.1888112
B31: UL = U2 = | C31: UIN - U1 = | D31: =$Q$10-D30 -> 0 | E31: =$Q$10-E30 -> 5.1428571 | F31: =$Q$10-F30 -> 6.5454545 | G31: =$Q$10-G30 -> 7.2 | H31: =$Q$10-H30 -> 7.5789474 | I31: =$Q$10-I30 -> 7.826087 | J31: =$Q$10-J30 -> 8 | K31: =$Q$10-K30 -> 8.1290323 | ... AM31: =$Q$10-AM30 -> 8.8111888
B32: RTotal = | C32: R11 + (R22||RL)= | D32: =IF(D27=0,$W$7,$W$7 + (1/(1/$W$8 + 1/D27))) -> 2400 | E32: =$W$7 + (1/(1/$W$8 + 1/E27)) -> 3278.0488 | F32: =$W$7 + (1/(1/$W$8 + 1/F27)) -> 3965.2174 | G32: =$W$7 + (1/(1/$W$8 + 1/G27)) -> 4517.6471 | H32: =$W$7 + (1/(1/$W$8 + 1/H27)) -> 4971.4286 | I32: =$W$7 + (1/(1/$W$8 + 1/I27)) -> 5350.8197 | J32: =$W$7 + (1/(1/$W$8 + 1/J27)) -> 5672.7273 | K32: =$W$7 + (1/(1/$W$8 + 1/K27)) -> 5949.2958 | L32: =$W$7 + (1/(1/$W$8 + 1/L27)) -> 6189.4737 | ... AM32: =$W$7 + (1/(1/$W$8 + 1/AM27)) -> 8371.564
B33: ITotal = | C33: UIN / RTotal = | D33: =$Q$10/D32 -> 0.005 | E33: =$Q$10/E32 -> 0.0036607143 | F33: =$Q$10/F32 -> 0.0030263158 | G33: =$Q$10/G32 -> 0.00265625 | H33: =$Q$10/H32 -> 0.0024137931 | I33: =$Q$10/I32 -> 0.0022426471 | J33: =$Q$10/J32 -> 0.0021153846 | K33: =$Q$10/K32 -> 0.0020170455 | ... AM33: =$Q$10/AM32 -> 0.0014334239
B34: U1 = | C34: R11 * ITotal = | D34: =$W$7*D33 -> 12 | E34: =$W$7*E33 -> 8.7857143 | F34: =$W$7*F33 -> 7.2631579 | G34: =$W$7*G33 -> 6.375 | H34: =$W$7*H33 -> 5.7931034 | I34: =$W$7*I33 -> 5.3823529 | J34: =$W$7*J33 -> 5.0769231 | K34: =$W$7*K33 -> 4.8409091 | ... AM34: =$W$7*AM33 -> 3.4402174
B35: UL = U2 = | C35: UIN - U1 = | D35: =$Q$10-D34 -> 0 | E35: =$Q$10-E34 -> 3.2142857 | F35: =$Q$10-F34 -> 4.7368421 | G35: =$Q$10-G34 -> 5.625 | H35: =$Q$10-H34 -> 6.2068966 | I35: =$Q$10-I34 -> 6.6176471 | J35: =$Q$10-J34 -> 6.9230769 | K35: =$Q$10-K34 -> 7.1590909 | ... AM35: =$Q$10-AM34 -> 8.5597826
B41: =_xlfn.CONCAT("UL = f(RL) R1/R2 =",Q11) -> UL = f(RL) R1/R2 =0.333333333333333
B42: =_xlfn.CONCAT("UL = f(RL) R11/R22 =",W11) -> UL = f(RL) R11/R22 =0.333333333333333

Sheet Magnetismus
C2: Magnetismus

Sheet Einheitenvorsätze
C2: Einheiten-Vorsätze
A6: Symbol | B6: Vorsatz | C6: Faktor | D6: Zehnerpotenz | E6: Vielfaches
A7: Q | B7: Quetta | C7: 1e+30 | D7: 10³⁰ | E7: 30
A8: R | B8: Ronna | C8: 1e+27 | D8: 10²⁷ | E8: 27
A9: Y | B9: Yotta | C9: 1e+24 | D9: 10²⁴ | E9: 24
A10: Z | B10: Zetta | C10: 1e+21 | D10: 10²¹ | E10: 21
A11: E | B11: Exa | C11: 1e+18 | D11: 10¹⁸ | E11: 18 | H11: Test | L11: zum rechnen | O11: zum darstellen
A12: P | B12: Peta | C12: 1e+15 | D12: 10¹⁵ | E12: 15 | H12: 5.23 | I12: k | J12: s | L12: =H12*VLOOKUP(I12, CHOOSE({1,2,3,4}, Einheitenvorsätze!A:A, Einheitenvorsätze!B:B, Einheitenvorsätze!C:C, Einheitenvorsätze!D:D), 3, FALSE) -> 5230 | M12: =J12 -> s | O12: =IF(I12=Einheitenvorsätze!$A$19,_xlfn.CONCAT(H12,J12),_xlfn.CONCAT(H12," * ",VLOOKUP(I12, CHOOSE({1,2,3,4}, Einheitenvorsätze!A:A, Einheitenvorsätze!B:B, Einheitenvorsätze!C:C, Einheitenvorsätze!D:D), 4, FALSE),J12)) -> 5.23 * 10³s
A13: T | B13: Tera | C13: 1000000000000 | D13: 10¹² | E13: 12
A14: G | B14: Giga | C14: 1000000000 | D14: 10⁹ | E14: 9
A15: Me | B15: Mega | C15: 1000000 | D15: 10⁶ | E15: 6
A16: k | B16: Kilo | C16: 1000 | D16: 10³ | E16: 3 | H16: Vorsatz | I16: =VLOOKUP(I12, CHOOSE({1,2,3,4}, Einheitenvorsätze!A:A, Einheitenvorsätze!B:B, Einheitenvorsätze!C:C, Einheitenvorsätze!D:D), 2, FALSE) -> Kilo
A17: h | B17: Hekto | C17: 100 | D17: 10² | E17: 2 | H17: Faktor | I17: =VLOOKUP(I12, CHOOSE({1,2,3,4}, Einheitenvorsätze!A:A, Einheitenvorsätze!B:B, Einheitenvorsätze!C:C, Einheitenvorsätze!D:D), 3, FALSE) -> 1000
A18: da | B18: Deka | C18: 10 | D18: 10¹ | E18: 1 | H18: Zehnerpotenz | I18: =VLOOKUP(I12, CHOOSE({1,2,3,4}, Einheitenvorsätze!A:A, Einheitenvorsätze!B:B, Einheitenvorsätze!C:C, Einheitenvorsätze!D:D), 4, FALSE) -> 10³
A19: – | B19: (Basiseinheit) | C19: 1 | D19: 10⁰ | E19: 0 | H19: =E6 -> Vielfaches | I19: =VLOOKUP(I12, CHOOSE({1,2,3,4,5}, Einheitenvorsätze!A:A, Einheitenvorsätze!B:B, Einheitenvorsätze!C:C, Einheitenvorsätze!D:D, Einheitenvorsätze!E:E), 5, FALSE) -> 3
A20: d | B20: Dezi | C20: 0.1 | D20: 10⁻¹ | E20: -1
A21: c | B21: Zenti | C21: 0.01 | D21: 10⁻² | E21: -2
A22: m | B22: Milli | C22: 0.001 | D22: 10⁻³ | E22: -3
A23: µ | B23: Mikro | C23: 1e-06 | D23: 10⁻⁶ | E23: -6
A24: n | B24: Nano | C24: 1e-09 | D24: 10⁻⁹ | E24: -9
A25: p | B25: Piko | C25: 1e-12 | D25: 10⁻¹² | E25: -12
A26: f | B26: Femto | C26: 1e-15 | D26: 10⁻¹⁵ | E26: -15
A27: a | B27: Atto | C27: 1e-18 | D27: 10⁻¹⁸ | E27: -18
A28: z | B28: Zepto | C28: 1e-21 | D28: 10⁻²¹ | E28: -21
A29: y | B29: Yocto | C29: 1e-24 | D29: 10⁻²⁴ | E29: -24
A30: r | B30: Ronto | C30: 1e-30 | D30: 10⁻²⁷ | E30: -27
A31: q | B31: Quekto | C31: 1e-27 | D31: 10⁻³⁰ | E31: -30
A36: Griechische Buchstaben
A37: Name | B37: Groß | C37: Klein
A38: Alpha | B38: Α | C38: α
A39: Beta | B39: Β | C39: β
A40: Gamma | B40: Γ | C40: γ
A41: Delta | B41: Δ | C41: δ
A42: Epsilon | B42: Ε | C42: ε
A43: Zeta | B43: Ζ | C43: ζ
A44: Eta | B44: Η | C44: η
A45: Theta | B45: Θ | C45: θ
A46: Iota | B46: Ι | C46: ι
A47: Kappa | B47: Κ | C47: κ
A48: Lambda | B48: Λ | C48: λ
...

Sheet Edizio_Bestellungen
C8: S3 + S3 T13
C11: Bestellung
C17: 3 | E17: 3 | G17: 3 | I17: 20 | K17: 1 | M17: 1 | O17: 1 | Q17: 1 | T17: 1
C23: 1 | E23: 3 | G23: 1 | I23: 1 | K23: 1 | M23: 2 * AP | Q23: 3

Sheet Elektronische Schaltzeichen
C2: Elektronische Schaltzeichen

Sheet LCR-Glieder an Wechselspannung
C2: RCL-Glieder (Serieschaltung) an Wechselspannung | R2: Ja | T2: Linear | AA2: Lösung: | AB2: Ja
R3: Nein | T3: Logarithmisch
AB19: Gegeben: | AD19: Gesucht:
C20: R = | D20: 1.5 | E20: k | F20: =Einheitenvorsätze!B61 -> Ω | G20: =VLOOKUP(E20, CHOOSE({1,2,3,4,5}, Einheitenvorsätze!A:A, Einheitenvorsätze!B:B, Einheitenvorsätze!C:C, Einheitenvorsätze!D:D, Einheitenvorsätze!E:E), 5, FALSE) -> 3 | H20: =D20*VLOOKUP(E20, CHOOSE({1,2,3,4}, Einheitenvorsätze!A:A, Einheitenvorsätze!B:B, Einheitenvorsätze!C:C, Einheitenvorsätze!D:D), 3, FALSE) -> 1500 | I20: =C20 -> R = | J20: =IF(E20=Einheitenvorsätze!$A$19,_xlfn.CONCAT(D20,F20),_xlfn.CONCAT(D20," * ",VLOOKUP(E20, CHOOSE({1,2,3,4}, Einheitenvorsätze!A:A, Einheitenvorsätze!B:B, Einheitenvorsätze!C:C, Einheitenvorsätze!D:D), 4, FALSE),F20)) -> 1.5 * 10³Ω | K20: =IF(E20=Einheitenvorsätze!$A$19,_xlfn.CONCAT(D20,F20),_xlfn.CONCAT(D20,E20,F20)) -> 1.5kΩ | L20: =_xlfn.CONCAT(I20,K20) -> R = 1.5kΩ | M20: =_xlfn.CONCAT(I20,J20) -> R = 1.5 * 10³Ω | AB20: =$L$20 -> R = 1.5kΩ | AD20: =IF($AB$2=$R$2,$L$25,_xlfn.CONCAT($C$25,"?")) -> ω = 6283.1853(1/s) | AF20: =$H$20 -> 1500 | AG20: R: | AH20: 0 | AI20: =IF($AB$2=$R$2,AF20,0) -> 1500 | AK20: 0 | AL20: 0
C21: C = | D21: 0.1 | E21: µ | F21: F | G21: =VLOOKUP(E21, CHOOSE({1,2,3,4,5}, Einheitenvorsätze!A:A, Einheitenvorsätze!B:B, Einheitenvorsätze!C:C, Einheitenvorsätze!D:D, Einheitenvorsätze!E:E), 5, FALSE) -> -6 | H21: =D21*VLOOKUP(E21, CHOOSE({1,2,3,4}, Einheitenvorsätze!A:A, Einheitenvorsätze!B:B, Einheitenvorsätze!C:C, Einheitenvorsätze!D:D), 3, FALSE) -> 1e-07 | I21: =C21 -> C = | J21: =IF(E21=Einheitenvorsätze!$A$19,_xlfn.CONCAT(D21,F21),_xlfn.CONCAT(D21," * ",VLOOKUP(E21, CHOOSE({1,2,3,4}, Einheitenvorsätze!A:A, Einheitenvorsätze!B:B, Einheitenvorsätze!C:C, Einheitenvorsätze!D:D), 4, FALSE),F21)) -> 0.1 * 10⁻⁶F | K21: =IF(E21=Einheitenvorsätze!$A$19,_xlfn.CONCAT(D21,F21),_xlfn.CONCAT(D21,E21,F21)) -> 0.1µF | L21: =_xlfn.CONCAT(I21,K21) -> C = 0.1µF | M21: =_xlfn.CONCAT(I21,J21) -> C = 0.1 * 10⁻⁶F | AB21: =$L$21 -> C = 0.1µF | AD21: =IF($AB$2=$R$2,$L$28,_xlfn.CONCAT($C$28,"?")) -> Blindwiderstand XC = 1.59kΩ | AF21: =$H$28 -> 1590 | AG21: XC: | AH21: 0 | AI21: 0 | AK21: 0 | AL21: =IF($AB$2=$R$2,-AF21,0) -> -1590
C22: L = | D22: 80 | E22: m | F22: H | G22: =VLOOKUP(E22, CHOOSE({1,2,3,4,5}, Einheitenvorsätze!A:A, Einheitenvorsätze!B:B, Einheitenvorsätze!C:C, Einheitenvorsätze!D:D, Einheitenvorsätze!E:E), 5, FALSE) -> -3 | H22: =D22*VLOOKUP(E22, CHOOSE({1,2,3,4}, Einheitenvorsätze!A:A, Einheitenvorsätze!B:B, Einheitenvorsätze!C:C, Einheitenvorsätze!D:D), 3, FALSE) -> 0.08 | I22: =C22 -> L = | J22: =IF(E22=Einheitenvorsätze!$A$19,_xlfn.CONCAT(D22,F22),_xlfn.CONCAT(D22," * ",VLOOKUP(E22, CHOOSE({1,2,3,4}, Einheitenvorsätze!A:A, Einheitenvorsätze!B:B, Einheitenvorsätze!C:C, Einheitenvorsätze!D:D), 4, FALSE),F22)) -> 80 * 10⁻³H | K22: =IF(E22=Einheitenvorsätze!$A$19,_xlfn.CONCAT(D22,F22),_xlfn.CONCAT(D22,E22,F22)) -> 80mH | L22: =_xlfn.CONCAT(I22,K22) -> L = 80mH | M22: =_xlfn.CONCAT(I22,J22) -> L = 80 * 10⁻³H | AB22: =$L$23 -> f =1kHZ | AD22: =IF($AB$2=$R$2,$L$32,_xlfn.CONCAT($C$32,"?")) -> Scheinwiderstand ZRC = 2.19kΩ | AF22: =ABS(MAX(AF20:AF21))*1.1 -> 1749 | AG22: MAX: | AH22: =-AF22 -> -1749 | AI22: =AF22 -> 1749 | AK22: 0 | AL22: 0
C23: f = | D23: 1 | E23: k | F23: HZ | G23: =VLOOKUP(E23, CHOOSE({1,2,3,4,5}, Einheitenvorsätze!A:A, Einheitenvorsätze!B:B, Einheitenvorsätze!C:C, Einheitenvorsätze!D:D, Einheitenvorsätze!E:E), 5, FALSE) -> 3 | H23: =D23*VLOOKUP(E23, CHOOSE({1,2,3,4}, Einheitenvorsätze!A:A, Einheitenvorsätze!B:B, Einheitenvorsätze!C:C, Einheitenvorsätze!D:D), 3, FALSE) -> 1000 | I23: =C23 -> f = | J23: =IF(E23=Einheitenvorsätze!$A$19,_xlfn.CONCAT(D23,F23),_xlfn.CONCAT(D23," * ",VLOOKUP(E23, CHOOSE({1,2,3,4}, Einheitenvorsätze!A:A, Einheitenvorsätze!B:B, Einheitenvorsätze!C:C, Einheitenvorsätze!D:D), 4, FALSE),F23)) -> 1 * 10³HZ | K23: =IF(E23=Einheitenvorsätze!$A$19,_xlfn.CONCAT(D23,F23),_xlfn.CONCAT(D23,E23,F23)) -> 1kHZ | L23: =_xlfn.CONCAT(I23,K23) -> f =1kHZ | M23: =_xlfn.CONCAT(I23,J23) -> f =1 * 10³HZ | AD23: =IF($AB$2=$R$2,$T$32,_xlfn.CONCAT($O$32,"?")) -> φ = -46.7° | AH23: 0 | AI23: 0 | AK23: =AH22 -> -1749 | AL23: =AI22 -> 1749
AD24: =IF($AB$2=$R$2,$X$32,_xlfn.CONCAT($V$32,"?")) -> cos(φ) = 0.7 | AH24: 0 | AI24: =AI20 -> 1500 | AK24: 0 | AL24: =AL21 -> -1590
C25: ω = | D25: =ROUND((2*PI()*H23 / 10^G25),4) -> 6283.1853 | E25: – | F25: (1/s) | G25: =VLOOKUP(E25, CHOOSE({1,2,3,4,5}, Einheitenvorsätze!A:A, Einheitenvorsätze!B:B, Einheitenvorsätze!C:C, Einheitenvorsätze!D:D, Einheitenvorsätze!E:E), 5, FALSE) -> 0 | H25: =D25*VLOOKUP(E25, CHOOSE({1,2,3,4}, Einheitenvorsätze!A:A, Einheitenvorsätze!B:B, Einheitenvorsätze!C:C, Einheitenvorsätze!D:D), 3, FALSE) -> 6283.1853 | I25: =C25 -> ω = | J25: =IF(E25=Einheitenvorsätze!$A$19,_xlfn.CONCAT(D25,F25),_xlfn.CONCAT(D25," * ",VLOOKUP(E25, CHOOSE({1,2,3,4}, Einheitenvorsätze!A:A, Einheitenvorsätze!B:B, Einheitenvorsätze!C:C, Einheitenvorsätze!D:D), 4, FALSE),F25)) -> 6283.1853(1/s) | K25: =IF(E25=Einheitenvorsätze!$A$19,_xlfn.CONCAT(D25,F25),_xlfn.CONCAT(D25,E25,F25)) -> 6283.1853(1/s) | L25: =_xlfn.CONCAT(I25,K25) -> ω = 6283.1853(1/s) | M25: =_xlfn.CONCAT(I25,J25) -> ω = 6283.1853(1/s)
C28: Blindwiderstand XC = | D28: =ROUND((1/((D25*D21)*10^(G25+G21)))/10^G28,2) -> 1.59 | E28: k | F28: =F20 -> Ω | G28: =VLOOKUP(E28, CHOOSE({1,2,3,4,5}, Einheitenvorsätze!A:A, Einheitenvorsätze!B:B, Einheitenvorsätze!C:C, Einheitenvorsätze!D:D, Einheitenvorsätze!E:E), 5, FALSE) -> 3 | H28: =D28*VLOOKUP(E28, CHOOSE({1,2,3,4}, Einheitenvorsätze!A:A, Einheitenvorsätze!B:B, Einheitenvorsätze!C:C, Einheitenvorsätze!D:D), 3, FALSE) -> 1590 | I28: =C28 -> Blindwiderstand XC = | J28: =IF(E28=Einheitenvorsätze!$A$19,_xlfn.CONCAT(D28,F28),_xlfn.CONCAT(D28," * ",VLOOKUP(E28, CHOOSE({1,2,3,4}, Einheitenvorsätze!A:A, Einheitenvorsätze!B:B, Einheitenvorsätze!C:C, Einheitenvorsätze!D:D), 4, FALSE),F28)) -> 1.59 * 10³Ω | K28: =IF(E28=Einheitenvorsätze!$A$19,_xlfn.CONCAT(D28,F28),_xlfn.CONCAT(D28,E28,F28)) -> 1.59kΩ | L28: =_xlfn.CONCAT(I28,K28) -> Blindwiderstand XC = 1.59kΩ | M28: =_xlfn.CONCAT(I28,J28) -> Blindwiderstand XC = 1.59 * 10³Ω
C29: Blindwiderstand XL = | D29: =ROUND((((D25*D22)*10^(G25+G22))/10^G29),4) -> 502.6548 | E29: – | F29: =F20 -> Ω | G29: =VLOOKUP(E29, CHOOSE({1,2,3,4,5}, Einheitenvorsätze!A:A, Einheitenvorsätze!B:B, Einheitenvorsätze!C:C, Einheitenvorsätze!D:D, Einheitenvorsätze!E:E), 5, FALSE) -> 0 | H29: =D29*VLOOKUP(E29, CHOOSE({1,2,3,4}, Einheitenvorsätze!A:A, Einheitenvorsätze!B:B, Einheitenvorsätze!C:C, Einheitenvorsätze!D:D), 3, FALSE) -> 502.6548 | I29: =C29 -> Blindwiderstand XL = | J29: =IF(E29=Einheitenvorsätze!$A$19,_xlfn.CONCAT(D29,F29),_xlfn.CONCAT(D29," * ",VLOOKUP(E29, CHOOSE({1,2,3,4}, Einheitenvorsätze!A:A, Einheitenvorsätze!B:B, Einheitenvorsätze!C:C, Einheitenvorsätze!D:D), 4, FALSE),F29)) -> 502.6548Ω | K29: =IF(E29=Einheitenvorsätze!$A$19,_xlfn.CONCAT(D29,F29),_xlfn.CONCAT(D29,E29,F29)) -> 502.6548Ω | L29: =_xlfn.CONCAT(I29,K29) -> Blindwiderstand XL = 502.6548Ω | M29: =_xlfn.CONCAT(I29,J29) -> Blindwiderstand XL = 502.6548Ω
C31: Serieschaltung:
C32: Scheinwiderstand ZRC = | D32: =ROUND(SQRT(H20^2 + H28^2) / 10^G32,2) -> 2.19 | E32: k | F32: =F29 -> Ω | G32: =VLOOKUP(E32, CHOOSE({1,2,3,4,5}, Einheitenvorsätze!A:A, Einheitenvorsätze!B:B, Einheitenvorsätze!C:C, Einheitenvorsätze!D:D, Einheitenvorsätze!E:E), 5, FALSE) -> 3 | H32: =D32*VLOOKUP(E32, CHOOSE({1,2,3,4}, Einheitenvorsätze!A:A, Einheitenvorsätze!B:B, Einheitenvorsätze!C:C, Einheitenvorsätze!D:D), 3, FALSE) -> 2190 | I32: =C32 -> Scheinwiderstand ZRC = | J32: =IF(E32=Einheitenvorsätze!$A$19,_xlfn.CONCAT(D32,F32),_xlfn.CONCAT(D32," * ",VLOOKUP(E32, CHOOSE({1,2,3,4}, Einheitenvorsätze!A:A, Einheitenvorsätze!B:B, Einheitenvorsätze!C:C, Einheitenvorsätze!D:D), 4, FALSE),F32)) -> 2.19 * 10³Ω | K32: =IF(E32=Einheitenvorsätze!$A$19,_xlfn.CONCAT(D32,F32),_xlfn.CONCAT(D32,E32,F32)) -> 2.19kΩ | L32: =_xlfn.CONCAT(I32,K32) -> Scheinwiderstand ZRC = 2.19kΩ | M32: =_xlfn.CONCAT(I32,J32) -> Scheinwiderstand ZRC = 2.19 * 10³Ω | O32: φ = | P32: =ATAN2(H20,-H28) -> -0.81451614 | Q32: rad | R32: =DEGREES(P32) -> -46.668337 | S32: ° | T32: =_xlfn.CONCAT(O32,ROUND(R32,1),S32) -> φ = -46.7° | V32: cos(φ) = | W32: =COS(RADIANS(R32)) -> 0.68622043 | X32: =_xlfn.CONCAT(V32,ROUND(W32,1)) -> cos(φ) = 0.7
C33: Scheinwiderstand ZRL = | D33: =ROUND(SQRT(H20^2 + H29^2)/10^G33,2) -> 1.58 | E33: k | F33: =F29 -> Ω | G33: =VLOOKUP(E33, CHOOSE({1,2,3,4,5}, Einheitenvorsätze!A:A, Einheitenvorsätze!B:B, Einheitenvorsätze!C:C, Einheitenvorsätze!D:D, Einheitenvorsätze!E:E), 5, FALSE) -> 3 | H33: =D33*VLOOKUP(E33, CHOOSE({1,2,3,4}, Einheitenvorsätze!A:A, Einheitenvorsätze!B:B, Einheitenvorsätze!C:C, Einheitenvorsätze!D:D), 3, FALSE) -> 1580 | I33: =C33 -> Scheinwiderstand ZRL = | J33: =IF(E33=Einheitenvorsätze!$A$19,_xlfn.CONCAT(D33,F33),_xlfn.CONCAT(D33," * ",VLOOKUP(E33, CHOOSE({1,2,3,4}, Einheitenvorsätze!A:A, Einheitenvorsätze!B:B, Einheitenvorsätze!C:C, Einheitenvorsätze!D:D), 4, FALSE),F33)) -> 1.58 * 10³Ω | K33: =IF(E33=Einheitenvorsätze!$A$19,_xlfn.CONCAT(D33,F33),_xlfn.CONCAT(D33,E33,F33)) -> 1.58kΩ | L33: =_xlfn.CONCAT(I33,K33) -> Scheinwiderstand ZRL = 1.58kΩ | M33: =_xlfn.CONCAT(I33,J33) -> Scheinwiderstand ZRL = 1.58 * 10³Ω | O33: φ = | P33: =ATAN2(H20,H29) -> 0.32334259 | Q33: rad | R33: =DEGREES(P33) -> 18.526166 | S33: ° | T33: =_xlfn.CONCAT(O33,ROUND(R33,1),S33) -> φ = 18.5° | V33: cos(φ) = | W33: =COS(RADIANS(R33)) -> 0.94817865 | X33: =_xlfn.CONCAT(V33,ROUND(W33,1)) -> cos(φ) = 0.9
B34: =IF(H28=H29,"ohmsch",IF(H28>H29,"kapazitiv","induktiv")) -> kapazitiv | C34: Scheinwiderstand ZRLC = | D34: =ROUND(SQRT(H20^2 + (H28-H29)^2)/10^G34,2) -> 1.85 | E34: k | F34: =F28 -> Ω | G34: =VLOOKUP(E34, CHOOSE({1,2,3,4,5}, Einheitenvorsätze!A:A, Einheitenvorsätze!B:B, Einheitenvorsätze!C:C, Einheitenvorsätze!D:D, Einheitenvorsätze!E:E), 5, FALSE) -> 3 | H34: =D34*VLOOKUP(E34, CHOOSE({1,2,3,4}, Einheitenvorsätze!A:A, Einheitenvorsätze!B:B, Einheitenvorsätze!C:C, Einheitenvorsätze!D:D), 3, FALSE) -> 1850 | I34: =C34 -> Scheinwiderstand ZRLC = | J34: =IF(E34=Einheitenvorsätze!$A$19,_xlfn.CONCAT(D34,F34),_xlfn.CONCAT(D34," * ",VLOOKUP(E34, CHOOSE({1,2,3,4}, Einheitenvorsätze!A:A, Einheitenvorsätze!B:B, Einheitenvorsätze!C:C, Einheitenvorsätze!D:D), 4, FALSE),F34)) -> 1.85 * 10³Ω | K34: =IF(E34=Einheitenvorsätze!$A$19,_xlfn.CONCAT(D34,F34),_xlfn.CONCAT(D34,E34,F34)) -> 1.85kΩ | L34: =_xlfn.CONCAT(I34,K34) -> Scheinwiderstand ZRLC = 1.85kΩ | M34: =_xlfn.CONCAT(I34,J34) -> Scheinwiderstand ZRLC = 1.85 * 10³Ω | O34: φ = | P34: =ATAN2(H20,H29-H28) -> -0.62724054 | Q34: rad | R34: =DEGREES(P34) -> -35.938236 | S34: ° | T34: =_xlfn.CONCAT(O34,ROUND(R34,1),S34) -> φ = -35.9° | V34: cos(φ) = | W34: =COS(RADIANS(R34)) -> 0.80965015 | X34: =_xlfn.CONCAT(V34,ROUND(W34,1)) -> cos(φ) = 0.8
AB37: Gegeben: | AD37: Gesucht:
C38: Kompensation: XC = XL | AB38: =$L$20 -> R = 1.5kΩ | AD38: =IF($AB$2=$R$2,$L$25,_xlfn.CONCAT($C$25,"?")) -> ω = 6283.1853(1/s) | AF38: =$H$20 -> 1500 | AG38: R: | AH38: 0 | AI38: =IF($AB$2=$R$2,AF38,0) -> 1500 | AK38: 0 | AL38: 0
C39: 1/2*π*f*C = 2*π*f*L | AB39: =$L$22 -> L = 80mH | AD39: =IF($AB$2=$R$2,$L$29,_xlfn.CONCAT($C$29,"?")) -> Blindwiderstand XL = 502.6548Ω | AF39: =$H$29 -> 502.6548 | AG39: XL: | AH39: 0 | AI39: 0 | AK39: 0 | AL39: =IF($AB$2=$R$2,AF39,0) -> 502.6548
AB40: =$L$23 -> f =1kHZ | AD40: =IF($AB$2=$R$2,$L$33,_xlfn.CONCAT($C$33,"?")) -> Scheinwiderstand ZRL = 1.58kΩ | AF40: =ABS(MAX(AF38:AF39))*1.1 -> 1650 | AG40: MAX: | AH40: =-AF40 -> -1650 | AI40: =AF40 -> 1650 | AK40: 0 | AL40: 0
C41: Logarithmisch | D41: 1.6 | AD41: =IF($AB$2=$R$2,$T$33,_xlfn.CONCAT($O$33,"?")) -> φ = 18.5° | AH41: 0 | AI41: 0 | AK41: =AH40 -> -1650 | AL41: =AI40 -> 1650
C42: Frequenz f [HZ] = | D42: 1 | E42: =IF($C$41=$T$2, D42+$D$41,D42*$D$41) -> 1.6 | F42: =IF($C$41=$T$2, E42+$D$41,E42*$D$41) -> 2.56 | G42: =IF($C$41=$T$2, F42+$D$41,F42*$D$41) -> 4.096 | H42: =IF($C$41=$T$2, G42+$D$41,G42*$D$41) -> 6.5536 | I42: =IF($C$41=$T$2, H42+$D$41,H42*$D$41) -> 10.48576 | J42: =IF($C$41=$T$2, I42+$D$41,I42*$D$41) -> 16.777216 | K42: =IF($C$41=$T$2, J42+$D$41,J42*$D$41) -> 26.843546 | L42: =IF($C$41=$T$2, K42+$D$41,K42*$D$41) -> 42.949673 | ... X42: =IF($C$41=$T$2, W42+$D$41,W42*$D$41) -> 12089.258 | AD42: =IF($AB$2=$R$2,$X$33,_xlfn.CONCAT($V$33,"?")) -> cos(φ) = 0.9 | AH42: 0 | AI42: =AI38 -> 1500 | AK42: 0 | AL42: =AL39 -> 502.6548
C43: Kreisfrequenz ω [s-1] = | D43: =2*PI()*D42 -> 6.2831853 | E43: =2*PI()*E42 -> 10.053096 | F43: =2*PI()*F42 -> 16.084954 | G43: =2*PI()*G42 -> 25.735927 | H43: =2*PI()*H42 -> 41.177483 | I43: =2*PI()*I42 -> 65.883973 | J43: =2*PI()*J42 -> 105.41436 | K43: =2*PI()*K42 -> 168.66297 | ... X43: =2*PI()*X42 -> 75959.049
C44: Blindwiderstand XC [Ω] = | D44: =1/(D43*$H$21) -> 1591549.4 | E44: =1/(E43*$H$21) -> 994718.39 | F44: =1/(F43*$H$21) -> 621699 | G44: =1/(G43*$H$21) -> 388561.87 | H44: =1/(H43*$H$21) -> 242851.17 | I44: =1/(I43*$H$21) -> 151781.98 | J44: =1/(J43*$H$21) -> 94863.738 | K44: =1/(K43*$H$21) -> 59289.837 | ... X44: =1/(X43*$H$21) -> 131.64988
C45: Blindwiderstand XL [Ω] = | D45: =D43*$H$22 -> 0.50265482 | E45: =E43*$H$22 -> 0.80424772 | F45: =F43*$H$22 -> 1.2867964 | G45: =G43*$H$22 -> 2.0588742 | H45: =H43*$H$22 -> 3.2941987 | I45: =I43*$H$22 -> 5.2707179 | J45: =J43*$H$22 -> 8.4331486 | K45: =K43*$H$22 -> 13.493038 | ... X45: =X43*$H$22 -> 6076.724
C46: Scheinwiderstand ZRC [Ω] = | D46: =$H$20+D44 -> 1593049.4 | E46: =$H$20+E44 -> 996218.39 | F46: =$H$20+F44 -> 623199 | G46: =$H$20+G44 -> 390061.87 | H46: =$H$20+H44 -> 244351.17 | I46: =$H$20+I44 -> 153281.98 | J46: =$H$20+J44 -> 96363.738 | K46: =$H$20+K44 -> 60789.837 | ... X46: =$H$20+X44 -> 1631.6499
C47: Scheinwiderstand ZRL [Ω] = | D47: =$H$20+D45 -> 1500.5027 | E47: =$H$20+E45 -> 1500.8042 | F47: =$H$20+F45 -> 1501.2868 | G47: =$H$20+G45 -> 1502.0589 | H47: =$H$20+H45 -> 1503.2942 | I47: =$H$20+I45 -> 1505.2707 | J47: =$H$20+J45 -> 1508.4331 | K47: =$H$20+K45 -> 1513.493 | ... X47: =$H$20+X45 -> 7576.724
C48: Tiefpass mit C: Uout / Uin (Frequenzgang) | D48: =D44/D46 -> 0.99905841 | E48: =E44/E46 -> 0.99849431 | F48: =F44/F46 -> 0.99759306 | G48: =G44/G46 -> 0.99615446 | H48: =H44/H46 -> 0.99386129 | I48: =I44/I46 -> 0.99021411 | J48: =J44/J46 -> 0.98443398 | K48: =K44/K46 -> 0.97532482 | ... X48: =X44/X46 -> 0.08068513
C49: Hochpass mit L: Uout / Uin (Frequenzgang) | D49: =D45/D47 -> 0.00033499096 | E49: =E45/E47 -> 0.00053587783 | F49: =F45/F47 -> 0.00085712893 | G49: =G45/G47 -> 0.0013707014 | H49: =H45/H47 -> 0.00219132 | I49: =I45/I47 -> 0.0035015083 | J49: =J45/J47 -> 0.0055906678 | K49: =K45/K47 -> 0.0089151634 | ... X49: =X45/X47 -> 0.80202525
C50: Grenzfrequenz
AP52: 1
AF58: =$H$20 -> 1500 | AG58: R: | AH58: 0 | AI58: =IF($AB$2=$R$2,AF58,0) -> 1500 | AK58: 0 | AL58: 0
AB59: Gegeben: | AD59: Gesucht: | AF59: =$H$28 -> 1590 | AG59: XC: | AH59: 0 | AI59: 0 | AK59: 0 | AL59: =IF($AB$2=$R$2,-AF59,0) -> -1590
AB60: =$L$20 -> R = 1.5kΩ | AD60: =IF($AB$2=$R$2,$L$25,_xlfn.CONCAT($C$25,"?")) -> ω = 6283.1853(1/s) | AF60: =$H$29 -> 502.6548 | AG60: XL: | AH60: 0 | AI60: 0 | AK60: 0 | AL60: =IF($AB$2=$R$2,AF60,0) -> 502.6548
AB61: =$L$22 -> L = 80mH | AD61: =IF($AB$2=$R$2,$L$29,_xlfn.CONCAT($C$29,"?")) -> Blindwiderstand XL = 502.6548Ω | AG61: XLC: | AH61: 0 | AI61: 0 | AK61: 0 | AL61: =AL59+AL60 -> -1087.3452
AB62: =$L$21 -> C = 0.1µF | AD62: =IF($AB$2=$R$2,$L$28,_xlfn.CONCAT($C$28,"?")) -> Blindwiderstand XC = 1.59kΩ
AB63: =$L$23 -> f =1kHZ | AD63: =IF($AB$2=$R$2,$L$34,_xlfn.CONCAT($C$33,"?")) -> Scheinwiderstand ZRLC = 1.85kΩ
AD64: =IF($AB$2=$R$2,$T$34,_xlfn.CONCAT($O$34,"?")) -> φ = -35.9° | AG64: ZRLC: | AH64: 0 | AI64: =AI58 -> 1500 | AK64: 0 | AL64: =AL61 -> -1087.3452
AD65: =IF($AB$2=$R$2,$X$34,_xlfn.CONCAT($V$34,"?")) -> cos(φ) = 0.8 | AF65: =ABS(MAX(AF58:AF60))*1.1 -> 1749 | AG65: MAX: | AH65: =-AF65 -> -1749 | AI65: =AF65 -> 1749 | AK65: 0 | AL65: 0
AD66: =IF($AB$2=$R$2,_xlfn.CONCAT("Die Schaltung ist ",$B$34),"Ist die Schaltung induktiv oder kapazitiv?") -> Die Schaltung ist kapazitiv | AH66: 0 | AI66: 0 | AK66: =AH65 -> -1749 | AL66: =AI65 -> 1749
AH67: 0 | AI67: =AI59 -> 0 | AK67: 0 | AL67: =AL60 -> 502.6548

Sheet Kondensator an Gleichspannung
C2: Kondensator an Gleichspannung | R2: Ja
R3: Nein
H4: Lösung: | I4: Ja
C6: U0 = | D6: 55 | E6: – | F6: V | G6: =VLOOKUP(E6, CHOOSE({1,2,3,4,5}, Einheitenvorsätze!A:A, Einheitenvorsätze!B:B, Einheitenvorsätze!C:C, Einheitenvorsätze!D:D, Einheitenvorsätze!E:E), 5, FALSE) -> 0 | H6: =D6*VLOOKUP(E6, CHOOSE({1,2,3,4}, Einheitenvorsätze!A:A, Einheitenvorsätze!B:B, Einheitenvorsätze!C:C, Einheitenvorsätze!D:D), 3, FALSE) -> 55 | I6: =C6 -> U0 = | J6: =IF(E6=Einheitenvorsätze!$A$19,_xlfn.CONCAT(D6,F6),_xlfn.CONCAT(D6," * ",VLOOKUP(E6, CHOOSE({1,2,3,4}, Einheitenvorsätze!A:A, Einheitenvorsätze!B:B, Einheitenvorsätze!C:C, Einheitenvorsätze!D:D), 4, FALSE),F6)) -> 55V | K6: =IF(E6=Einheitenvorsätze!$A$19,_xlfn.CONCAT(D6,F6),_xlfn.CONCAT(D6,E6,F6)) -> 55V | L6: =_xlfn.CONCAT(I6,K6) -> U0 = 55V | M6: =_xlfn.CONCAT(I6,J6) -> U0 = 55V
C7: R = | D7: 1500 | E7: k | F7: =Einheitenvorsätze!B61 -> Ω | G7: =VLOOKUP(E7, CHOOSE({1,2,3,4,5}, Einheitenvorsätze!A:A, Einheitenvorsätze!B:B, Einheitenvorsätze!C:C, Einheitenvorsätze!D:D, Einheitenvorsätze!E:E), 5, FALSE) -> 3 | H7: =D7*VLOOKUP(E7, CHOOSE({1,2,3,4}, Einheitenvorsätze!A:A, Einheitenvorsätze!B:B, Einheitenvorsätze!C:C, Einheitenvorsätze!D:D), 3, FALSE) -> 1500000 | I7: =C7 -> R = | J7: =IF(E7=Einheitenvorsätze!$A$19,_xlfn.CONCAT(D7,F7),_xlfn.CONCAT(D7," * ",VLOOKUP(E7, CHOOSE({1,2,3,4}, Einheitenvorsätze!A:A, Einheitenvorsätze!B:B, Einheitenvorsätze!C:C, Einheitenvorsätze!D:D), 4, FALSE),F7)) -> 1500 * 10³Ω | K7: =IF(E7=Einheitenvorsätze!$A$19,_xlfn.CONCAT(D7,F7),_xlfn.CONCAT(D7,E7,F7)) -> 1500kΩ | L7: =_xlfn.CONCAT(I7,K7) -> R = 1500kΩ | M7: =_xlfn.CONCAT(I7,J7) -> R = 1500 * 10³Ω
C8: C = | D8: 12 | E8: n | F8: F | G8: =VLOOKUP(E8, CHOOSE({1,2,3,4,5}, Einheitenvorsätze!A:A, Einheitenvorsätze!B:B, Einheitenvorsätze!C:C, Einheitenvorsätze!D:D, Einheitenvorsätze!E:E), 5, FALSE) -> -9 | H8: =D8*VLOOKUP(E8, CHOOSE({1,2,3,4}, Einheitenvorsätze!A:A, Einheitenvorsätze!B:B, Einheitenvorsätze!C:C, Einheitenvorsätze!D:D), 3, FALSE) -> 1.2e-08 | I8: =C8 -> C = | J8: =IF(E8=Einheitenvorsätze!$A$19,_xlfn.CONCAT(D8,F8),_xlfn.CONCAT(D8," * ",VLOOKUP(E8, CHOOSE({1,2,3,4}, Einheitenvorsätze!A:A, Einheitenvorsätze!B:B, Einheitenvorsätze!C:C, Einheitenvorsätze!D:D), 4, FALSE),F8)) -> 12 * 10⁻⁹F | K8: =IF(E8=Einheitenvorsätze!$A$19,_xlfn.CONCAT(D8,F8),_xlfn.CONCAT(D8,E8,F8)) -> 12nF | L8: =_xlfn.CONCAT(I8,K8) -> C = 12nF | M8: =_xlfn.CONCAT(I8,J8) -> C = 12 * 10⁻⁹F
C9: t = | D9: 12 | E9: m | F9: s | G9: =VLOOKUP(E9, CHOOSE({1,2,3,4,5}, Einheitenvorsätze!A:A, Einheitenvorsätze!B:B, Einheitenvorsätze!C:C, Einheitenvorsätze!D:D, Einheitenvorsätze!E:E), 5, FALSE) -> -3 | H9: =D9*VLOOKUP(E9, CHOOSE({1,2,3,4}, Einheitenvorsätze!A:A, Einheitenvorsätze!B:B, Einheitenvorsätze!C:C, Einheitenvorsätze!D:D), 3, FALSE) -> 0.012 | I9: =C9 -> t = | J9: =IF(E9=Einheitenvorsätze!$A$19,_xlfn.CONCAT(D9,F9),_xlfn.CONCAT(D9," * ",VLOOKUP(E9, CHOOSE({1,2,3,4}, Einheitenvorsätze!A:A, Einheitenvorsätze!B:B, Einheitenvorsätze!C:C, Einheitenvorsätze!D:D), 4, FALSE),F9)) -> 12 * 10⁻³s | K9: =IF(E9=Einheitenvorsätze!$A$19,_xlfn.CONCAT(D9,F9),_xlfn.CONCAT(D9,E9,F9)) -> 12ms | L9: =_xlfn.CONCAT(I9,K9) -> t = 12ms | M9: =_xlfn.CONCAT(I9,J9) -> t = 12 * 10⁻³s | O9: =_xlfn.CONCAT(C9,"-",Einheitenvorsätze!C56," * ln(1 - UC/U0)") -> t = -τ * ln(1 - UC/U0) | R9: =-D11 * LN(1 - D12/D6) -> 0.012000026
C11: =_xlfn.CONCAT(" ",Einheitenvorsätze!C56," = ") -> τ = | D11: =ROUND(D7*D8 * 10^(G7+G8+G11),4) -> 0.018 | E11: – | F11: s | G11: =VLOOKUP(E11, CHOOSE({1,2,3,4,5}, Einheitenvorsätze!A:A, Einheitenvorsätze!B:B, Einheitenvorsätze!C:C, Einheitenvorsätze!D:D, Einheitenvorsätze!E:E), 5, FALSE) -> 0 | H11: =D11*VLOOKUP(E11, CHOOSE({1,2,3,4}, Einheitenvorsätze!A:A, Einheitenvorsätze!B:B, Einheitenvorsätze!C:C, Einheitenvorsätze!D:D), 3, FALSE) -> 0.018 | I11: =C11 -> τ = | J11: =IF(E11=Einheitenvorsätze!$A$19,_xlfn.CONCAT(D11,F11),_xlfn.CONCAT(D11," * ",VLOOKUP(E11, CHOOSE({1,2,3,4}, Einheitenvorsätze!A:A, Einheitenvorsätze!B:B, Einheitenvorsätze!C:C, Einheitenvorsätze!D:D), 4, FALSE),F11)) -> 0.018s | K11: =IF(E11=Einheitenvorsätze!$A$19,_xlfn.CONCAT(D11,F11),_xlfn.CONCAT(D11,E11,F11)) -> 0.018s | L11: =_xlfn.CONCAT(I11,K11) -> τ = 0.018s | M11: =_xlfn.CONCAT(I11,J11) -> τ = 0.018s | N11: =_xlfn.CONCAT(C11," R*C") -> τ = R*C | O11: =_xlfn.CONCAT(C11,"-t/ln(1 - UC/U0)") -> τ = -t/ln(1 - UC/U0) | R11: =-D9 / LN(1 - D12/D6) -> 17.99996
B12: Laden: | C12: =_xlfn.CONCAT(" UC = ") -> UC = | D12: =ROUND(H6*(1-EXP(-H9/H11))/10^G12,4) -> 26.7621 | E12: – | F12: V | G12: =VLOOKUP(E12, CHOOSE({1,2,3,4,5}, Einheitenvorsätze!A:A, Einheitenvorsätze!B:B, Einheitenvorsätze!C:C, Einheitenvorsätze!D:D, Einheitenvorsätze!E:E), 5, FALSE) -> 0 | H12: =D12*VLOOKUP(E12, CHOOSE({1,2,3,4}, Einheitenvorsätze!A:A, Einheitenvorsätze!B:B, Einheitenvorsätze!C:C, Einheitenvorsätze!D:D), 3, FALSE) -> 26.7621 | I12: =C12 -> UC = | J12: =IF(E12=Einheitenvorsätze!$A$19,_xlfn.CONCAT(D12,F12),_xlfn.CONCAT(D12," * ",VLOOKUP(E12, CHOOSE({1,2,3,4}, Einheitenvorsätze!A:A, Einheitenvorsätze!B:B, Einheitenvorsätze!C:C, Einheitenvorsätze!D:D), 4, FALSE),F12)) -> 26.7621V | K12: =IF(E12=Einheitenvorsätze!$A$19,_xlfn.CONCAT(D12,F12),_xlfn.CONCAT(D12,E12,F12)) -> 26.7621V | L12: =_xlfn.CONCAT(I12,K12) -> UC = 26.7621V | M12: =_xlfn.CONCAT(I12,J12) -> UC = 26.7621V | N12: Laden: | O12: =_xlfn.CONCAT("UC(t) = U0(1 - e^(-t/",Einheitenvorsätze!C56,"))") -> UC(t) = U0(1 - e^(-t/τ)) | R12: =D6*(1 - EXP(-D9/D11)) -> 55
B13: Entladen: | C13: =_xlfn.CONCAT(" UC = ") -> UC = | D13: =ROUND(H6*(EXP(-H9/H11))/10^G12,4) -> 28.2379 | E13: – | F13: V | G13: =VLOOKUP(E13, CHOOSE({1,2,3,4,5}, Einheitenvorsätze!A:A, Einheitenvorsätze!B:B, Einheitenvorsätze!C:C, Einheitenvorsätze!D:D, Einheitenvorsätze!E:E), 5, FALSE) -> 0 | H13: =D13*VLOOKUP(E13, CHOOSE({1,2,3,4}, Einheitenvorsätze!A:A, Einheitenvorsätze!B:B, Einheitenvorsätze!C:C, Einheitenvorsätze!D:D), 3, FALSE) -> 28.2379 | I13: =C13 -> UC = | J13: =IF(E13=Einheitenvorsätze!$A$19,_xlfn.CONCAT(D13,F13),_xlfn.CONCAT(D13," * ",VLOOKUP(E13, CHOOSE({1,2,3,4}, Einheitenvorsätze!A:A, Einheitenvorsätze!B:B, Einheitenvorsätze!C:C, Einheitenvorsätze!D:D), 4, FALSE),F13)) -> 28.2379V | K13: =IF(E13=Einheitenvorsätze!$A$19,_xlfn.CONCAT(D13,F13),_xlfn.CONCAT(D13,E13,F13)) -> 28.2379V | L13: =_xlfn.CONCAT(I13,K13) -> UC = 28.2379V | M13: =_xlfn.CONCAT(I13,J13) -> UC = 28.2379V | N13: Entladen: | O13: =_xlfn.CONCAT("UC(t) = U0(e^(-t/",Einheitenvorsätze!C56,"))") -> UC(t) = U0(e^(-t/τ))
N16: (-t/RC) = | O16: =-H9/H11 -> -0.66666667 | R16: =_xlfn.CONCAT("t / ", Einheitenvorsätze!C56) -> t / τ | S16: (1 - e^(-t/RC))
N17: e^(-t/RC) = | O17: =EXP(O16) -> 0.51341712 | R17: 0 | S17: =1-EXP(-R17) -> 0
I18: Gegeben: | K18: Gesucht: | N18: 1 - e^(-t/RC) = | O18: =1-O17 -> 0.48658288 | R18: 1 | S18: =1-EXP(-R18) -> 0.63212056
I19: =$L$7 -> R = 1500kΩ | K19: =IF($I$4=$R$2,$L$11,_xlfn.CONCAT($C$11,"?")) -> τ = 0.018s | R19: 2 | S19: =1-EXP(-R19) -> 0.86466472
I20: =$L$8 -> C = 12nF | K20: =IF($I$4=$R$2,$L$12,_xlfn.CONCAT($C$12,"?")) -> UC = 26.7621V | L20: =IF($I$4=$R$2,$H$12/$H$6,"") -> 0.48658364 | R20: 3 | S20: =1-EXP(-R20) -> 0.95021293
I21: =$L$6 -> U0 = 55V | R21: 4 | S21: =1-EXP(-R21) -> 0.98168436
I22: =$L$9 -> t = 12ms | R22: 5 | S22: =1-EXP(-R22) -> 0.99326205
R23: 6 | S23: =1-EXP(-R23) -> 0.99752125
B30: Increment: | C30: 2 | D30: =_xlfn.CONCAT(IF(E9="–","",E9),F9) -> ms | Y30: Asymptote:
B31: t [s] | C31: =C32*10^$G$9 -> 0 | D31: =D32*10^$G$9 -> 0.002 | E31: =E32*10^$G$9 -> 0.004 | F31: =F32*10^$G$9 -> 0.006 | G31: =G32*10^$G$9 -> 0.008 | H31: =H32*10^$G$9 -> 0.01 | I31: =I32*10^$G$9 -> 0.012 | J31: =J32*10^$G$9 -> 0.014 | ... W31: =W32*10^$G$9 -> 0.04 | Y31: =C32 -> 0 | Z31: =W32 -> 40
B32: =_xlfn.CONCAT("t [",D30,"]") -> t [ms] | C32: 0 | D32: =C32+$C$30 -> 2 | E32: =D32+$C$30 -> 4 | F32: =E32+$C$30 -> 6 | G32: =F32+$C$30 -> 8 | H32: =G32+$C$30 -> 10 | I32: =H32+$C$30 -> 12 | J32: =I32+$C$30 -> 14 | K32: =J32+$C$30 -> 16 | ... W32: =V32+$C$30 -> 40 | Y32: =$D$6 -> 55 | Z32: =Y32 -> 55
A33: Ladekurve: | B33: UC(t) = U0(1 - e^(-t/RC)) | C33: =$D$6*(1-EXP(-C31/($H$7*$H$8))) -> 0 | D33: =$D$6*(1-EXP(-D31/($H$7*$H$8))) -> 5.7838376 | E33: =$D$6*(1-EXP(-E31/($H$7*$H$8))) -> 10.959443 | F33: =$D$6*(1-EXP(-F31/($H$7*$H$8))) -> 15.590778 | G33: =$D$6*(1-EXP(-G31/($H$7*$H$8))) -> 19.735079 | H33: =$D$6*(1-EXP(-H31/($H$7*$H$8))) -> 23.443562 | I33: =$D$6*(1-EXP(-I31/($H$7*$H$8))) -> 26.762058 | J33: =$D$6*(1-EXP(-J31/($H$7*$H$8))) -> 29.73158 | ... W33: =$D$6*(1-EXP(-W31/($H$7*$H$8))) -> 49.039759
A34: Entladekurve: | B34: UC(t) = U0(e^(-t/RC)) | C34: =$D$6*EXP(-C32/($H$7*$H$8)) -> 55 | D34: =$D$6*EXP(-D32/($H$7*$H$8)) -> 3.0578787e-47 | E34: =$D$6*EXP(-E32/($H$7*$H$8)) -> 1.7001131e-95 | F34: =$D$6*EXP(-F32/($H$7*$H$8)) -> 9.4522541e-144 | G34: =$D$6*EXP(-G32/($H$7*$H$8)) -> 5.2552448e-192 | H34: =$D$6*EXP(-H32/($H$7*$H$8)) -> 2.9218002e-240 | I34: =$D$6*EXP(-I32/($H$7*$H$8)) -> 1.6244565e-288 | J34: =$D$6*EXP(-J32/($H$7*$H$8)) -> 0 | ... W34: =$D$6*EXP(-W32/($H$7*$H$8)) -> 0
I39: Vertikale:
I40: =H11/10^G11 -> 0.018 | J40: =I40 -> 0.018
I41: 0 | J41: =$H$6*(1 - EXP(-1)) -> 34.766631
N42: Inc: | O42: 1
I43: Horizontale: | N43: x = | O43: 0 | P43: =O43+$O$42 -> 1 | Q43: =P43+$O$42 -> 2 | R43: =Q43+$O$42 -> 3 | S43: =R43+$O$42 -> 4 | T43: =S43+$O$42 -> 5 | U43: =T43+$O$42 -> 6 | V43: =U43+$O$42 -> 7 | W43: =V43+$O$42 -> 8 | ... Y43: =X43+$O$42 -> 10
I44: 0 | J44: =J40 -> 0.018 | N44: y = 1 - e-x = | O44: =1-EXP(-O43) -> 0 | P44: =1-EXP(-P43) -> 0.63212056 | Q44: =1-EXP(-Q43) -> 0.86466472 | R44: =1-EXP(-R43) -> 0.95021293 | S44: =1-EXP(-S43) -> 0.98168436 | T44: =1-EXP(-T43) -> 0.99326205 | U44: =1-EXP(-U43) -> 0.99752125 | V44: =1-EXP(-V43) -> 0.99908812 | ... Y44: =1-EXP(-Y43) -> 0.9999546
I45: =J41 -> 34.766631 | J45: =I45 -> 34.766631 | N45: y = e-x = | O45: =EXP(-O43) -> 1 | P45: =EXP(-P43) -> 0.36787944 | Q45: =EXP(-Q43) -> 0.13533528 | R45: =EXP(-R43) -> 0.049787068 | S45: =EXP(-S43) -> 0.018315639 | T45: =EXP(-T43) -> 0.006737947 | U45: =EXP(-U43) -> 0.0024787522 | V45: =EXP(-V43) -> 0.00091188197 | ... Y45: =EXP(-Y43) -> 4.539993e-05
H72: Vertikale:
H73: =H11/10^G11 -> 0.018 | I73: =H73 -> 0.018
H74: 0 | I74: =$H$6*(EXP(-1)) -> 20.233369
H76: Horizontale:
H77: 0 | I77: =I73 -> 0.018
H78: =I74 -> 20.233369 | I78: =H78 -> 20.233369

Sheet Quelle mit Innenwiderstand
C2: Quelle mit Innenwiderstand
J5: Daten der Quelle | N5: Leistungsanpassung: RL = Ri
J6: U0 = | K6: 1.55 | L6: [V] | N6: IAn = U0 / (2 * Ri) | O6: =K6/(2*K7) -> 1.1071429 | Q6: =K7 -> 0.7 | R6: =Q6 -> 0.7
J7: Ri = | K7: 0.7 | L7: [Ω] | N7: UAn = U0 / 2 | O7: =K6/2 -> 0.775 | Q7: 0 | R7: =MAX(O6:O8) -> 1.1071429
N8: PAn = IAn * UAn | O8: =O6*O7 -> 0.85803571
I10: Increment: | J10: 0.1
I11: RL | J11: 0 | K11: =J11+$J$10 -> 0.1 | L11: =K11+$J$10 -> 0.2 | M11: =L11+$J$10 -> 0.3 | N11: =M11+$J$10 -> 0.4 | O11: =N11+$J$10 -> 0.5 | P11: =O11+$J$10 -> 0.6 | Q11: =P11+$J$10 -> 0.7 | R11: =Q11+$J$10 -> 0.8 | ... AD11: =AC11+$J$10 -> 2
I12: I = U0/(Ri + RL) | J12: =$K$6/($K$7+J11) -> 2.2142857 | K12: =$K$6/($K$7+K11) -> 1.9375 | L12: =$K$6/($K$7+L11) -> 1.7222222 | M12: =$K$6/($K$7+M11) -> 1.55 | N12: =$K$6/($K$7+N11) -> 1.4090909 | O12: =$K$6/($K$7+O11) -> 1.2916667 | P12: =$K$6/($K$7+P11) -> 1.1923077 | Q12: =$K$6/($K$7+Q11) -> 1.1071429 | ... AD12: =$K$6/($K$7+AD11) -> 0.57407407
I13: U = RL * I | J13: =J11*J12 -> 0 | K13: =K11*K12 -> 0.19375 | L13: =L11*L12 -> 0.34444444 | M13: =M11*M12 -> 0.465 | N13: =N11*N12 -> 0.56363636 | O13: =O11*O12 -> 0.64583333 | P13: =P11*P12 -> 0.71538462 | Q13: =Q11*Q12 -> 0.775 | ... AD13: =AD11*AD12 -> 1.1481481
I14: PRL = U * I | J14: =J12*J13 -> 0 | K14: =K12*K13 -> 0.37539063 | L14: =L12*L13 -> 0.59320988 | M14: =M12*M13 -> 0.72075 | N14: =N12*N13 -> 0.79421488 | O14: =O12*O13 -> 0.83420139 | P14: =P12*P13 -> 0.85295858 | Q14: =Q12*Q13 -> 0.85803571 | ... AD14: =AD12*AD13 -> 0.65912209
I17: RL | J17: I = U0/(Ri + RL) | K17: U = RL * I
I18: [Ω] | J18: [mA] | K18: [V]
I19: 8 | J19: =$K$6/($K$7+I19)*1000 -> 178.16092 | K19: =I19*J19/1000 -> 1.4252874
I20: 4 | J20: =$K$6/($K$7+I20)*1000 -> 329.78723 | K20: =I20*J20/1000 -> 1.3191489
I21: 1.5 | J21: =$K$6/($K$7+I21)*1000 -> 704.54545 | K21: =I21*J21/1000 -> 1.0568182
I22: 0.75 | J22: =$K$6/($K$7+I22)*1000 -> 1068.9655 | K22: =I22*J22/1000 -> 0.80172414
I23: 0.3 | J23: =$K$6/($K$7+I23)*1000 -> 1550 | K23: =I23*J23/1000 -> 0.465
I24: 0 | J24: =$K$6/($K$7+I24)*1000 -> 2214.2857 | K24: =I24*J24/1000 -> 0

Sheet Schiefeebene
C2: Schiefe Ebene | L2: Winkelmasse | M2: Masse
L3: ° | M3: mg
L4: rad | M4: g
M5: kg
M6: t
D20: Masse: | E20: m = | F20: 5 | G20: g | K20: Reibungs-Koeffizient:
D21: Steigungswinkel: | E21: α = | F21: 31 | G21: ° | K21: Haftreibung (μₕ) = | L21: 0.6
E22: =E21 -> α = | F22: =IF(G21=G22,F21,F21*180/PI()) -> 31 | G22: =L3 -> ° | K22: Gleitreibung (μₖ) = | L22: 0.2
E23: =E21 -> α = | F23: =IF(G21=G23,F21,F21*PI()/180) -> 0.54105207 | G23: =L4 -> rad | K23: Winkel: Haften zu gleiten: | L23: =DEGREES(ATAN(L21)) -> 30.963757 | M23: [°] | O23: =L23*PI()/180 -> 0.5404195 | P23: [rad]
D24: Erdbeschleunigung: | E24: g = | F24: 9.81 | G24: m/s2 | K24: Winkel: Gleiten zu haften: | L24: =DEGREES(ATAN(L22)) -> 11.309932 | M24: [°] | O24: =L24*PI()/180 -> 0.19739556 | P24: [rad]
D26: Gewichtskraft: | E26: FG = | F26: m*g = | G26: =$F$20*$F$24 -> 49.05 | H26: =IF($G$20=$M$5,"N",IF($G$20=$M$6,"kN",IF($G$20=$M$4,"mN",IF($G$20=$M$3,"Mikro N","")))) -> mN
D27: Hangabtriebskraft: | E27: FH = | F27: FG * sin(α) = | G27: =$G$26*SIN($F$23) -> 25.262618 | H27: =H26 -> mN
D28: Normalkraft: | E28: FN = | F28: FG * cos(α) = | G28: =$G$26*COS($F$23) -> 42.044056 | H28: =H27 -> mN
D30: Haftreibungskraft: | E30: FRHaft = | F30: FN * μₕ = | G30: =$G$28*$L$21 -> 25.226434 | H30: =H28 -> mN
D31: Resultierende Hangabtriebskraft (Haftet): | E31: FHR_Haft = | F31: FH - FRHaft = | G31: =$G$27-G30 -> 0.036183915 | H31: =H30 -> mN | I31: =IF(G31>0,"Gleiten","Haftet") -> Gleiten | K31: Materialkombination | L31: Haftreibung (μₕ) | M31: Gleitreibung (μₖ) | O31: =D21 -> Steigungswinkel: | R31: Step: | S31: 5
D32: Gleitreibungskraft: | E32: FRGleit = | F32: FN * μₖ = | G32: =$G$28*$L$22 -> 8.4088112 | H32: =H31 -> mN | K32: Gummi auf trockenem Asphalt | L32: 0,9 – 1,0 | M32: 0,7 – 0,9 | O32: α = | P32: [°] | Q32: 0 | R32: =Q32+$S$31 -> 5 | S32: =R32+$S$31 -> 10 | T32: =S32+$S$31 -> 15 | U32: =T32+$S$31 -> 20 | V32: =U32+$S$31 -> 25 | W32: =V32+$S$31 -> 30 | X32: =W32+$S$31 -> 35 | Y32: =X32+$S$31 -> 40 | ... AI32: =AH32+$S$31 -> 90
D33: Resultierende Hangabtriebskraft (Gleitet): | E33: FHR _Gleit = | F33: FH - FRGleit = | G33: =$G$27-G32 -> 16.853806 | H33: =H32 -> mN | K33: Stahl auf Stahl (trocken) | L33: 0,6 – 0,8 | M33: 0,4 – 0,6 | O33: α = | P33: [rad] | Q33: =Q32*PI()/180 -> 0 | R33: =R32*PI()/180 -> 0.087266463 | S33: =S32*PI()/180 -> 0.17453293 | T33: =T32*PI()/180 -> 0.26179939 | U33: =U32*PI()/180 -> 0.34906585 | V33: =V32*PI()/180 -> 0.43633231 | W33: =W32*PI()/180 -> 0.52359878 | X33: =X32*PI()/180 -> 0.61086524 | ... AI33: =AI32*PI()/180 -> 1.5707963
K34: Holz auf Holz | L34: 0,4 – 0,6 | M34: 0,2 – 0,5 | O34: FH = | P34: =H26 -> mN | Q34: =$F$20*SIN(Q33)*$F$24 -> 0 | R34: =$F$20*SIN(R33)*$F$24 -> 4.2749892 | S34: =$F$20*SIN(S33)*$F$24 -> 8.5174431 | T34: =$F$20*SIN(T33)*$F$24 -> 12.695074 | U34: =$F$20*SIN(U33)*$F$24 -> 16.776088 | V34: =$F$20*SIN(V33)*$F$24 -> 20.729426 | W34: =$F$20*SIN(W33)*$F$24 -> 24.525 | X34: =$F$20*SIN(X33)*$F$24 -> 28.133924 | ... AI34: =$F$20*SIN(AI33)*$F$24 -> 49.05
K35: Eis auf Eis | L35: ~0,1 | M35: ~0,03 – 0,05 | O35: FRHaft = | P35: =P34 -> mN | Q35: =$F$20*$F$24*COS(Q33)*$L$21 -> 29.43 | R35: =$F$20*$F$24*COS(R33)*$L$21 -> 29.31801 | S35: =$F$20*$F$24*COS(S33)*$L$21 -> 28.982892 | T35: =$F$20*$F$24*COS(T33)*$L$21 -> 28.427197 | U35: =$F$20*$F$24*COS(U33)*$L$21 -> 27.655154 | V35: =$F$20*$F$24*COS(V33)*$L$21 -> 26.672638 | W35: =$F$20*$F$24*COS(W33)*$L$21 -> 25.487128 | X35: =$F$20*$F$24*COS(X33)*$L$21 -> 24.107645 | ... AI35: =$F$20*$F$24*COS(AI33)*$L$21 -> 1.802806e-15
K36: Teflon auf Teflon | L36: ~0,04 | M36: ~0,04 | O36: FRGleit = | P36: =P35 -> mN | Q36: =$F$20*$F$24*COS(Q33)*$L$22 -> 9.81 | R36: =$F$20*$F$24*COS(R33)*$L$22 -> 9.77267 | S36: =$F$20*$F$24*COS(S33)*$L$22 -> 9.6609641 | T36: =$F$20*$F$24*COS(T33)*$L$22 -> 9.4757324 | U36: =$F$20*$F$24*COS(U33)*$L$22 -> 9.2183846 | V36: =$F$20*$F$24*COS(V33)*$L$22 -> 8.8908794 | W36: =$F$20*$F$24*COS(W33)*$L$22 -> 8.4957092 | X36: =$F$20*$F$24*COS(X33)*$L$22 -> 8.0358816 | ... AI36: =$F$20*$F$24*COS(AI33)*$L$22 -> 6.0093532e-16
O37: FHR_Haft = | P37: =P36 -> mN | Q37: =Q34-Q35 -> -29.43 | R37: =R34-R35 -> -25.043021 | S37: =S34-S35 -> -20.465449 | T37: =T34-T35 -> -15.732123 | U37: =U34-U35 -> -10.879066 | V37: =V34-V35 -> -5.9432124 | W37: =W34-W35 -> -0.96212763 | X37: =X34-X35 -> 4.0262795 | ... AI37: =AI34-AI35 -> 49.05
O38: FHR _Gleit = | P38: =P37 -> mN | Q38: =Q34-Q36 -> -9.81 | R38: =R34-R36 -> -5.4976808 | S38: =S34-S36 -> -1.1435209 | T38: =T34-T36 -> 3.2193418 | U38: =U34-U36 -> 7.5577034 | V38: =V34-V36 -> 11.838546 | W38: =W34-W36 -> 16.029291 | X38: =X34-X36 -> 20.098043 | ... AI38: =AI34-AI36 -> 49.05
O39: a = FHR_Gleit / m = | Q39: =IF(Q38>0,Q38/$F$20,0) -> 0 | R39: =IF(R38>0,R38/$F$20,0) -> 0 | S39: =IF(S38>0,S38/$F$20,0) -> 0 | T39: =IF(T38>0,T38/$F$20,0) -> 0.64386836 | U39: =IF(U38>0,U38/$F$20,0) -> 1.5115407 | V39: =IF(V38>0,V38/$F$20,0) -> 2.3677093 | W39: =IF(W38>0,W38/$F$20,0) -> 3.2058582 | X39: =IF(X38>0,X38/$F$20,0) -> 4.0196085 | ... AI39: =IF(AI38>0,AI38/$F$20,0) -> 9.81
O40: a = g⋅(sin(α)−μₖ​⋅cos(α)) = | Q40: =IF(Q38>0,$F$24*(SIN(Q33)-$L$22*COS(Q33)),0) -> 0 | R40: =IF(R38>0,$F$24*(SIN(R33)-$L$22*COS(R33)),0) -> 0 | S40: =IF(S38>0,$F$24*(SIN(S33)-$L$22*COS(S33)),0) -> 0 | T40: =IF(T38>0,$F$24*(SIN(T33)-$L$22*COS(T33)),0) -> 0.64386836 | U40: =IF(U38>0,$F$24*(SIN(U33)-$L$22*COS(U33)),0) -> 1.5115407 | V40: =IF(V38>0,$F$24*(SIN(V33)-$L$22*COS(V33)),0) -> 2.3677093 | W40: =IF(W38>0,$F$24*(SIN(W33)-$L$22*COS(W33)),0) -> 3.2058582 | X40: =IF(X38>0,$F$24*(SIN(X33)-$L$22*COS(X33)),0) -> 4.0196085 | ... AI40: =IF(AI38>0,$F$24*(SIN(AI33)-$L$22*COS(AI33)),0) -> 9.81
AH41: Haften -> Gleiten | AI41: 0 | AJ41: =$L$23 -> 30.963757 | AK41: =$L$23 -> 30.963757
AI42: 0 | AJ42: 0 | AK42: =$F$24*(SIN(O23)-$L$22*COS(O23)) -> 3.3648022

Sheet Leistung bei Wechselstrom
C2: Leistung bei ein-phasigem Wechselstrom
E4: Û = | F4: 1 | G4: V | I4: φU = | J4: 120 | K4: ° = | L4: =RADIANS(J4) -> 2.0943951 | M4: rad | T4: x-Achse: | U4: =MIN(F8:AT8) -> 0 | V4: =MAX(F8:AT8) -> 400 | Y4: y-Achse: | Z4: 0 | AA4: 0 | AC4: Ja
E5: Î = | F5: 2 | G5: A | I5: φI = | J5: 90 | K5: ° = | L5: =RADIANS(J5) -> 1.5707963 | M5: rad | U5: 0 | V5: 0 | Z5: =MIN(F10:AT13) -> -2 | AA5: =MAX(F10:AT13) -> 2 | AC5: Nein
E7: Inc: | F7: 10
C8: x | E8: [°] | F8: 0 | G8: =F8+$F$7 -> 10 | H8: =G8+$F$7 -> 20 | I8: =H8+$F$7 -> 30 | J8: =I8+$F$7 -> 40 | K8: =J8+$F$7 -> 50 | L8: =K8+$F$7 -> 60 | M8: =L8+$F$7 -> 70 | N8: =M8+$F$7 -> 80 | ... AT8: =AS8+$F$7 -> 400
C9: x | E9: [rad] | F9: =F8*PI()/180 -> 0 | G9: =G8*PI()/180 -> 0.17453293 | H9: =H8*PI()/180 -> 0.34906585 | I9: =I8*PI()/180 -> 0.52359878 | J9: =J8*PI()/180 -> 0.6981317 | K9: =K8*PI()/180 -> 0.87266463 | L9: =L8*PI()/180 -> 1.0471976 | M9: =M8*PI()/180 -> 1.2217305 | ... AT9: =AT8*PI()/180 -> 6.981317
B10: Ja | C10: U(t) = UMomentan = | D10: Û * sin(x + φU) | E10: [V] | F10: =IF($B$10=$AC$4,$F$4*SIN(F9+$L$4),0) -> 0.8660254 | G10: =IF($B$10=$AC$4,$F$4*SIN(G9+$L$4),0) -> 0.76604444 | H10: =IF($B$10=$AC$4,$F$4*SIN(H9+$L$4),0) -> 0.64278761 | I10: =IF($B$10=$AC$4,$F$4*SIN(I9+$L$4),0) -> 0.5 | J10: =IF($B$10=$AC$4,$F$4*SIN(J9+$L$4),0) -> 0.34202014 | K10: =IF($B$10=$AC$4,$F$4*SIN(K9+$L$4),0) -> 0.17364818 | L10: =IF($B$10=$AC$4,$F$4*SIN(L9+$L$4),0) -> 1.2251485e-16 | M10: =IF($B$10=$AC$4,$F$4*SIN(M9+$L$4),0) -> -0.17364818 | ... AT10: =IF($B$10=$AC$4,$F$4*SIN(AT9+$L$4),0) -> 0.34202014
B11: Ja | C11: I(t) = IMomentan = | D11: Î * sin(x + φI) | E11: [A] | F11: =IF($B$11=$AC$4,$F$5*SIN(F9+$L$5),0) -> 2 | G11: =IF($B$11=$AC$4,$F$5*SIN(G9+$L$5),0) -> 1.9696155 | H11: =IF($B$11=$AC$4,$F$5*SIN(H9+$L$5),0) -> 1.8793852 | I11: =IF($B$11=$AC$4,$F$5*SIN(I9+$L$5),0) -> 1.7320508 | J11: =IF($B$11=$AC$4,$F$5*SIN(J9+$L$5),0) -> 1.5320889 | K11: =IF($B$11=$AC$4,$F$5*SIN(K9+$L$5),0) -> 1.2855752 | L11: =IF($B$11=$AC$4,$F$5*SIN(L9+$L$5),0) -> 1 | M11: =IF($B$11=$AC$4,$F$5*SIN(M9+$L$5),0) -> 0.68404029 | ... AT11: =IF($B$11=$AC$4,$F$5*SIN(AT9+$L$5),0) -> 1.5320889
B12: Nein | C12: P(t) = PMomentan = | D12: =IF($J$4=$J$5,"Umomentan^2 / R","Nicht gleichphasig") -> Nicht gleichphasig | E12: [W] | F12: =IF($B$12=$AC$4,IF($J$4=$J$5,F10^2,0),0) -> 0 | G12: =IF($B$12=$AC$4,IF($J$4=$J$5,G10^2,0),0) -> 0 | H12: =IF($B$12=$AC$4,IF($J$4=$J$5,H10^2,0),0) -> 0 | I12: =IF($B$12=$AC$4,IF($J$4=$J$5,I10^2,0),0) -> 0 | J12: =IF($B$12=$AC$4,IF($J$4=$J$5,J10^2,0),0) -> 0 | K12: =IF($B$12=$AC$4,IF($J$4=$J$5,K10^2,0),0) -> 0 | L12: =IF($B$12=$AC$4,IF($J$4=$J$5,L10^2,0),0) -> 0 | M12: =IF($B$12=$AC$4,IF($J$4=$J$5,M10^2,0),0) -> 0 | ... AT12: =IF($B$12=$AC$4,IF($J$4=$J$5,AT10^2,0),0) -> 0
B13: Ja | C13: P(t) = PMomentan = | D13: U(t) * I(t) | E13: [W] | F13: =IF($B$13=$AC$4,F10*F11,0) -> 1.7320508 | G13: =IF($B$13=$AC$4,G10*G11,0) -> 1.508813 | H13: =IF($B$13=$AC$4,H10*H11,0) -> 1.2080455 | I13: =IF($B$13=$AC$4,I10*I11,0) -> 0.8660254 | J13: =IF($B$13=$AC$4,J10*J11,0) -> 0.52400526 | K13: =IF($B$13=$AC$4,K10*K11,0) -> 0.22323779 | L13: =IF($B$13=$AC$4,L10*L11,0) -> 1.2251485e-16 | M13: =IF($B$13=$AC$4,M10*M11,0) -> -0.11878235 | ... AT13: =IF($B$13=$AC$4,AT10*AT11,0) -> 0.52400526
F17: =IF(AND($B$10=$AC$4,$B$11=$AC$4),IF(J4=J5,"Phasengleich (Ohmsche Last)",IF(J4>J5,"Spannung voreilend (Induktive Last)",IF(J4<J5,"Strom voreilend (Kapazitive Last)","ERROR"))),"") -> Spannung voreilend (Induktive Last)

Sheet Sinus_Cosinus
F2: Sinus / Cosinus / Tangens | BC2: Momentanwert Zeitbereich
L3: Ja | M3: [°] | BC3: =AZ10 -> 30 | BD3: =BC3 -> 30
L4: Nein | M4: [rad] | BC4: =IF(MIN(AZ12:AZ17)>0,0,MIN(AZ12:AZ17)) -> 0 | BD4: =IF(MAX(AZ12:AZ17) < 0,0,MAX(AZ12:AZ17)) -> 2
G9: Inc: | H9: 10 | AZ9: Momentanwerte | BC9: Vektoren | BG9: Vektor-Pfeile | BK9: Skala
C10: Radius | F10: x | G10: [°] | H10: 0 | I10: =H10+$H$9 -> 10 | J10: =I10+$H$9 -> 20 | K10: =J10+$H$9 -> 30 | L10: =K10+$H$9 -> 40 | M10: =L10+$H$9 -> 50 | N10: =M10+$H$9 -> 60 | O10: =N10+$H$9 -> 70 | P10: =O10+$H$9 -> 80 | ... AV10: =AU10+$H$9 -> 400 | AZ10: 30 | BA10: [°] | BC10: Betrag | BD10: Winkel [°] | BE10: x | BF10: y | BG10: x0 | BH10: x1 | BI10: y0 | BJ10: y1 | BK10: max | BL10: x0 | BM10: x1 | BN10: x2 | BO10: x3 | BP10: y0 | BQ10: y1 | BR10: y2 | BS10: y3
C11: Amplitude | D11: Phasenlage phi | E11: View | F11: x | G11: [rad] | H11: =IF($G$10=$M$3,H10*PI()/180,H10) -> 0 | I11: =IF($G$10=$M$3,I10*PI()/180,I10) -> 0.17453293 | J11: =IF($G$10=$M$3,J10*PI()/180,J10) -> 0.34906585 | K11: =IF($G$10=$M$3,K10*PI()/180,K10) -> 0.52359878 | L11: =IF($G$10=$M$3,L10*PI()/180,L10) -> 0.6981317 | M11: =IF($G$10=$M$3,M10*PI()/180,M10) -> 0.87266463 | N11: =IF($G$10=$M$3,N10*PI()/180,N10) -> 1.0471976 | O11: =IF($G$10=$M$3,O10*PI()/180,O10) -> 1.2217305 | ... AV11: =IF($G$10=$M$3,AV10*PI()/180,AV10) -> 6.981317 | AX11: Anzeigen: | AZ11: =IF($BA$10=$M$3,AZ10*PI()/180,H10) -> 0.52359878 | BA11: =M4 -> [rad] | BK11: {=MAX(ABS(BC12:BC16))} -> 4 | BL11: 0 | BM11: =BK11 -> 4 | BN11: 0 | BO11: =-BK11 -> -4 | BP11: =BM11 -> 4 | BQ11: 0 | BR11: =BO11 -> -4 | BS11: 0
C12: 4 | D12: 0 | F12: y1 = | G12: =_xlfn.CONCAT(C12, IF(D12=0," * sin(x) =",IF(D12<0,_xlfn.CONCAT(" * sin(x - ",ABS(D12),") ="),_xlfn.CONCAT(" * sin(x + ",D12,") =")))) -> 4 * sin(x) = | H12: =IF($AX$12=$L$3,$C$12*SIN(H11+RADIANS($D$12)),0) -> 0 | I12: =IF($AX$12=$L$3,$C$12*SIN(I11+RADIANS($D$12)),0) -> 0.69459271 | J12: =IF($AX$12=$L$3,$C$12*SIN(J11+RADIANS($D$12)),0) -> 1.3680806 | K12: =IF($AX$12=$L$3,$C$12*SIN(K11+RADIANS($D$12)),0) -> 2 | L12: =IF($AX$12=$L$3,$C$12*SIN(L11+RADIANS($D$12)),0) -> 2.5711504 | M12: =IF($AX$12=$L$3,$C$12*SIN(M11+RADIANS($D$12)),0) -> 3.0641778 | N12: =IF($AX$12=$L$3,$C$12*SIN(N11+RADIANS($D$12)),0) -> 3.4641016 | O12: =IF($AX$12=$L$3,$C$12*SIN(O11+RADIANS($D$12)),0) -> 3.7587705 | ... AV12: =IF($AX$12=$L$3,$C$12*SIN(AV11+RADIANS($D$12)),0) -> 2.5711504 | AX12: Ja | AZ12: =IF($AX$12=$L$3,$C$12 * SIN(AZ11 + RADIANS($D$12)),0) -> 2 | BC12: =IF($AX$12=$L$3,$C12,0) -> 4 | BD12: =$AZ$10+$D$12 -> 30 | BE12: =BC12*COS(RADIANS(BD12)) -> 3.4641016 | BF12: =BC12*SIN(RADIANS(BD12)) -> 2 | BG12: 0 | BH12: =BE12 -> 3.4641016 | BI12: 0 | BJ12: =BF12 -> 2
C13: 4 | D13: -90 | F13: y2 = | G13: =_xlfn.CONCAT(C13, IF(D13=0," * cos(x) =",IF(D13<0,_xlfn.CONCAT(" * cos(x - ",ABS(D13),") ="),_xlfn.CONCAT(" * cos(x + ",D13,") =")))) -> 4 * cos(x - 90) = | H13: =IF($AX$13=$L$3,$C$13*COS(H11+RADIANS($D$13)),0) -> 0 | I13: =IF($AX$13=$L$3,$C$13*COS(I11+RADIANS($D$13)),0) -> 0 | J13: =IF($AX$13=$L$3,$C$13*COS(J11+RADIANS($D$13)),0) -> 0 | K13: =IF($AX$13=$L$3,$C$13*COS(K11+RADIANS($D$13)),0) -> 0 | L13: =IF($AX$13=$L$3,$C$13*COS(L11+RADIANS($D$13)),0) -> 0 | M13: =IF($AX$13=$L$3,$C$13*COS(M11+RADIANS($D$13)),0) -> 0 | N13: =IF($AX$13=$L$3,$C$13*COS(N11+RADIANS($D$13)),0) -> 0 | O13: =IF($AX$13=$L$3,$C$13*COS(O11+RADIANS($D$13)),0) -> 0 | ... AV13: =IF($AX$13=$L$3,$C$13*COS(AV11+RADIANS($D$13)),0) -> 0 | AX13: Nein | AZ13: =IF($AX$13=$L$3,$C$13 * COS(AZ11+RADIANS(D13)),0) -> 0 | BC13: =IF($AX$13=$L$3,$C13,0) -> 0 | BD13: =$AZ$10+90+$D$13 -> 30 | BE13: =BC13*COS(RADIANS(BD13)) -> 0 | BF13: =BC13*SIN(RADIANS(BD13)) -> 0 | BG13: 0 | BH13: =BE13 -> 0 | BI13: 0 | BJ13: =BF13 -> 0
BK15: Hilfslinie_1 | BO15: Hilfslinie_2
F16: Y3 = | G16: Y1 + Y2 = | H16: =IF($AX$16=$L$3,H12+H13,0) -> 0 | I16: =IF($AX$16=$L$3,I12+I13,0) -> 0 | J16: =IF($AX$16=$L$3,J12+J13,0) -> 0 | K16: =IF($AX$16=$L$3,K12+K13,0) -> 0 | L16: =IF($AX$16=$L$3,L12+L13,0) -> 0 | M16: =IF($AX$16=$L$3,M12+M13,0) -> 0 | N16: =IF($AX$16=$L$3,N12+N13,0) -> 0 | O16: =IF($AX$16=$L$3,O12+O13,0) -> 0 | ... AV16: =IF($AX$16=$L$3,AV12+AV13,0) -> 0 | AX16: Nein | AZ16: =IF($AX$16=$L$3,AZ12+AZ13,0) -> 0 | BC16: =SQRT(BE16^2+BF16^2) -> 0 | BD16: =IF($AX$16=$L$3,DEGREES(ATAN2(BE16,BF16)),0) -> 0 | BE16: =IF($AX$16=$L$3,BE12+BE13,0) -> 0 | BF16: =IF($AX$16=$L$3,BF12+BF13,0) -> 0 | BG16: 0 | BH16: =BE16 -> 0 | BI16: 0 | BJ16: =BF16 -> 0 | BK16: =IF($AX$16=$L$3,BE13,0) -> 0 | BL16: =BE16 -> 0 | BM16: =IF($AX$16=$L$3,BF13,0) -> 0 | BN16: =BF16 -> 0 | BO16: =BE12 -> 3.4641016 | BP16: =BL16 -> 0 | BQ16: =IF($AX$16=$L$3,BF12,0) -> 0 | BR16: =BN16 -> 0
